Workbook

Sheet PROXY_SENSITIV_ANLYS_RESULT
B2: MEAN ABSOLUTE ERROR (MAE) =AVERAGE(ABS(seriesA -seriesB)) | J2: MEAN ABSOLUTE ALIGNMENT (MAA = 1 - MAE) =1 - (AVERAGE(ABS(seriesA -seriesB)))
B3: Values represent error between human responses and LLM proxy. | D3: Omission Probability (OP) Internal parameter for accuracy proxy | J3: Values represent alignment between human responses and LLM proxy. | L3: Omission Probability (OP) Internal parameter for accuracy proxy
D4: 0.1 | E4: 0.3 | F4: 0.5 | G4: 0.7 | H4: 0.9 | L4: 0.1 | M4: 0.3 | N4: 0.5 | O4: 0.7 | P4: 0.9
B5: Reasoning OpenAI API paramter for GPT models 5+ | C5: none | D5: =PROXY_SENSITIV_ANLYS_DATA!Q94 -> 0.13074074 | E5: =PROXY_SENSITIV_ANLYS_DATA!T94 -> 0.1237037 | F5: =PROXY_SENSITIV_ANLYS_DATA!W94 -> 0.11481481 | G5: =PROXY_SENSITIV_ANLYS_DATA!Z94 -> 0.15518519 | H5: =PROXY_SENSITIV_ANLYS_DATA!AC94 -> 0.2412963 | J5: Reasoning OpenAI API paramter for GPT models 5+ | K5: none | L5: =1-PROXY_SENSITIV_ANLYS_DATA!Q94 -> 0.86925926 | M5: =1-PROXY_SENSITIV_ANLYS_DATA!T94 -> 0.8762963 | N5: =1-PROXY_SENSITIV_ANLYS_DATA!W94 -> 0.88518519 | O5: =1-PROXY_SENSITIV_ANLYS_DATA!Z94 -> 0.84481481 | P5: =1-PROXY_SENSITIV_ANLYS_DATA!AC94 -> 0.7587037
C6: low | D6: =PROXY_SENSITIV_ANLYS_DATA!AF94 -> 0.14037037 | E6: =PROXY_SENSITIV_ANLYS_DATA!AI94 -> 0.11351852 | F6: =PROXY_SENSITIV_ANLYS_DATA!AL94 -> 0.097222222 | G6: =PROXY_SENSITIV_ANLYS_DATA!AO94 -> 0.12407407 | H6: =PROXY_SENSITIV_ANLYS_DATA!AR94 -> 0.22351852 | K6: low | L6: =1-PROXY_SENSITIV_ANLYS_DATA!AF94 -> 0.85962963 | M6: =1-PROXY_SENSITIV_ANLYS_DATA!AI94 -> 0.88648148 | N6: =1-PROXY_SENSITIV_ANLYS_DATA!AL94 -> 0.90277778 | O6: =1-PROXY_SENSITIV_ANLYS_DATA!AO94 -> 0.87592593 | P6: =1-PROXY_SENSITIV_ANLYS_DATA!AR94 -> 0.77648148
C7: medium | D7: =PROXY_SENSITIV_ANLYS_DATA!AU94 -> 0.14851852 | E7: =PROXY_SENSITIV_ANLYS_DATA!AX94 -> 0.11944444 | F7: =AVERAGE(PROXY_SENSITIV_ANLYS_DATA!BA94,PROXY_SENSITIV_ANLYS_DATA!G94,PROXY_SENSITIV_ANLYS_DATA!J94,PROXY_SENSITIV_ANLYS_DATA!M94) -> 0.095972222 | G7: =PROXY_SENSITIV_ANLYS_DATA!BD94 -> 0.13425926 | H7: =PROXY_SENSITIV_ANLYS_DATA!BG94 -> 0.24444444 | K7: medium | L7: =1-PROXY_SENSITIV_ANLYS_DATA!AU94 -> 0.85148148 | M7: =1-PROXY_SENSITIV_ANLYS_DATA!AX94 -> 0.88055556 | N7: =1-AVERAGE(PROXY_SENSITIV_ANLYS_DATA!BA94,PROXY_SENSITIV_ANLYS_DATA!G94,PROXY_SENSITIV_ANLYS_DATA!J94,PROXY_SENSITIV_ANLYS_DATA!M94) -> 0.90402778 | O7: =1-PROXY_SENSITIV_ANLYS_DATA!BD94 -> 0.86574074 | P7: =1-PROXY_SENSITIV_ANLYS_DATA!BG94 -> 0.75555556
E9: Values we used for the pilot experiment | M9: Values we used for the pilot experiment
B11: ROOT MEAN SQUARED ERROR (RMSE) =SQRT( AVERAGE( (seriesA -seriesB)^2 ) ) | J11: ROOT MEAN SQUARED ALIGNMENT (1 - RMSE) =1 - (SQRT( AVERAGE( (seriesA -seriesB)^2 ) ))
B12: Values represent error between human responses and LLM proxy. | D12: Omission Probability (OP) Internal parameter for accuracy proxy | J12: Values represent alignment between human responses and LLM proxy. | L12: Omission Probability (OP) Internal parameter for accuracy proxy
D13: 0.1 | E13: 0.3 | F13: 0.5 | G13: 0.7 | H13: 0.9 | L13: 0.1 | M13: 0.3 | N13: 0.5 | O13: 0.7 | P13: 0.9
B14: Reasoning OpenAI API paramter for GPT models 5+ | C14: none | D14: =PROXY_SENSITIV_ANLYS_DATA!Q95 -> 0.20655911 | E14: =PROXY_SENSITIV_ANLYS_DATA!T95 -> 0.18479218 | F14: =PROXY_SENSITIV_ANLYS_DATA!W95 -> 0.16555183 | G14: =PROXY_SENSITIV_ANLYS_DATA!Z95 -> 0.21743454 | H14: =PROXY_SENSITIV_ANLYS_DATA!AC95 -> 0.35319966 | J14: Reasoning OpenAI API paramter for GPT models 5+ | K14: none | L14: =1-PROXY_SENSITIV_ANLYS_DATA!Q95 -> 0.79344089 | M14: =1-PROXY_SENSITIV_ANLYS_DATA!T95 -> 0.81520782 | N14: =1-PROXY_SENSITIV_ANLYS_DATA!W95 -> 0.83444817 | O14: =1-PROXY_SENSITIV_ANLYS_DATA!Z95 -> 0.78256546 | P14: =1-PROXY_SENSITIV_ANLYS_DATA!AC95 -> 0.64680034
C15: low | D15: =PROXY_SENSITIV_ANLYS_DATA!AF95 -> 0.22599574 | E15: =PROXY_SENSITIV_ANLYS_DATA!AI95 -> 0.17355221 | F15: =PROXY_SENSITIV_ANLYS_DATA!AL95 -> 0.1485423 | G15: =PROXY_SENSITIV_ANLYS_DATA!AO95 -> 0.18002057 | H15: =PROXY_SENSITIV_ANLYS_DATA!AR95 -> 0.32802721 | K15: low | L15: =1-PROXY_SENSITIV_ANLYS_DATA!AF95 -> 0.77400426 | M15: =1-PROXY_SENSITIV_ANLYS_DATA!AI95 -> 0.82644779 | N15: =1-PROXY_SENSITIV_ANLYS_DATA!AL95 -> 0.8514577 | O15: =1-PROXY_SENSITIV_ANLYS_DATA!AO95 -> 0.81997943 | P15: =1-PROXY_SENSITIV_ANLYS_DATA!AR95 -> 0.67197279
C16: medium | D16: =PROXY_SENSITIV_ANLYS_DATA!AU95 -> 0.23005635 | E16: =PROXY_SENSITIV_ANLYS_DATA!AX95 -> 0.17828919 | F16: =PROXY_SENSITIV_ANLYS_DATA!BA95 -> 0.14621775 | G16: =PROXY_SENSITIV_ANLYS_DATA!BD95 -> 0.1917029 | H16: =PROXY_SENSITIV_ANLYS_DATA!BG95 -> 0.36479319 | K16: medium | L16: =1-PROXY_SENSITIV_ANLYS_DATA!AU95 -> 0.76994365 | M16: =1-PROXY_SENSITIV_ANLYS_DATA!AX95 -> 0.82171081 | N16: =1-PROXY_SENSITIV_ANLYS_DATA!BA95 -> 0.85378225 | O16: =1-PROXY_SENSITIV_ANLYS_DATA!BD95 -> 0.8082971 | P16: =1-PROXY_SENSITIV_ANLYS_DATA!BG95 -> 0.63520681
E18: Values we used for the pilot experiment | M18: Values we used for the pilot experiment

Sheet PROXY_SENSITIV_ANLYS_DATA
A1: CONDITION | B1: REAL STATE | C1: STATE SELECTION OPTIONS | D1: SURVEY 03 | F1: BASELINE | Reproduce 01 | I1: BASELINE | Reproduce 02 | L1: BASELINE | Reproduce 03 | P1: ID 20 | OP = 0.1 | REASON = none | S1: ID 21 | OP = 0.3 | REASON = none | V1: ID 22 | OP = 0.5 | REASON = none | Y1: ID 23 | OP = 0.7 | REASON = none | AB1: ID 24 | OP = 0.9 | REASON = none | AE1: ID 25 | OP = 0.1 | REASON = low | AH1: ID 26 | OP = 0.3 | REASON = low | AK1: ID 27 | OP = 0.5 | REASON = low | AN1: ID 28 | OP = 0.7 | REASON = low | AQ1: ID 29 | OP = 0.9 | REASON = low | AT1: ID 30 | OP = 0.1 | REASON = medium | AW1: ID 31 | OP = 0.3 | REASON = medium | AZ1: ID 32 | OP = 0.5 | REASON = medium | BC1: ID 33 | OP = 0.7 | REASON = medium | BF1: ID 34 | OP = 0.9 | REASON = medium
D2: HUMAN RESPONSE (%) | F2: PROXY RESPONSE (%) | G2: ABS DELTA | I2: PROXY RESPONSE (%) | J2: ABS DELTA | L2: PROXY RESPONSE (%) | M2: ABS DELTA | P2: PROXY RESPONSE (%) | Q2: ABS DELTA | S2: PROXY RESPONSE (%) | T2: ABS DELTA | V2: PROXY RESPONSE (%) | W2: ABS DELTA | Y2: PROXY RESPONSE (%) | Z2: ABS DELTA | AB2: PROXY RESPONSE (%) | AC2: ABS DELTA | AE2: PROXY RESPONSE (%) | AF2: ABS DELTA | AH2: PROXY RESPONSE (%) | AI2: ABS DELTA | AK2: PROXY RESPONSE (%) | AL2: ABS DELTA | AN2: PROXY RESPONSE (%) | AO2: ABS DELTA | AQ2: PROXY RESPONSE (%) | AR2: ABS DELTA | AT2: PROXY RESPONSE (%) | AU2: ABS DELTA | AW2: PROXY RESPONSE (%) | AX2: ABS DELTA | AZ2: PROXY RESPONSE (%) | BA2: ABS DELTA | BC2: PROXY RESPONSE (%) | BD2: ABS DELTA | BF2: PROXY RESPONSE (%) | BG2: ABS DELTA
A3: GPT4 | B3: Waiting for Input | C3: Waiting for Input | D3: =COUNTIFS(STUDY03_DATA!C:C,A3,STUDY03_DATA!D:D,B3,STUDY03_DATA!F:F,C3)/'META DATA'!$B$2 -> 0.73333333 | F3: {=LLM_WFI_14!S2:S7} -> 0.7 | G3: =ABS($D3-F3) -> 0.033333333 | I3: {=LLM_WFI_18!S2:S7} -> 0.7 | J3: =ABS($D3-I3) -> 0.033333333 | L3: {=LLM_WFI_19!S2:S7} -> 0.75 | M3: =ABS($D3-L3) -> 0.016666667 | P3: {=LLM_WFI_20!S2:S7} -> 0.8 | Q3: =ABS($D3-P3) -> 0.066666667 | S3: {=LLM_WFI_21!S2:S7} -> 0.9 | T3: =ABS($D3-S3) -> 0.16666667 | V3: {=LLM_WFI_22!S2:S7} -> 0.3 | W3: =ABS($D3-V3) -> 0.43333333 | Y3: {=LLM_WFI_23!S2:S7} -> 0.2 | Z3: =ABS($D3-Y3) -> 0.53333333 | AB3: {=LLM_WFI_24!S2:S7} -> 0.2 | AC3: =ABS($D3-AB3) -> 0.53333333 | AE3: {=LLM_WFI_25!S2:S7} -> 0.85 | AF3: =ABS($D3-AE3) -> 0.11666667 | AH3: {=LLM_WFI_26!S2:S7} -> 0.95 | AI3: =ABS($D3-AH3) -> 0.21666667 | AK3: {=LLM_WFI_27!S2:S7} -> 0.45 | AL3: =ABS($D3-AK3) -> 0.28333333 | AN3: {=LLM_WFI_28!S2:S7} -> 0.55 | AO3: =ABS($D3-AN3) -> 0.18333333 | AQ3: {=LLM_WFI_29!S2:S7} -> 0.1 | AR3: =ABS($D3-AQ3) -> 0.63333333 | AT3: {=LLM_WFI_30!S2:S7} -> 0.95 | AU3: =ABS($D3-AT3) -> 0.21666667 | AW3: {=LLM_WFI_31!S2:S7} -> 0.85 | AX3: =ABS($D3-AW3) -> 0.11666667 | AZ3: {=LLM_WFI_32!S2:S7} -> 0.5 | BA3: =ABS($D3-AZ3) -> 0.23333333 | BC3: {=LLM_WFI_33!S2:S7} -> 0.6 | BD3: =ABS($D3-BC3) -> 0.13333333 | BF3: {=LLM_WFI_34!S2:S7} -> 0.1 | BG3: =ABS($D3-BF3) -> 0.63333333 | BJ3: ACCURACY PROXY VALIDATION DATA (MEAN ABS ERROR = MAE) | ID 32
A4: GPT4 | B4: Waiting for Input | C4: Analyzing Object | D4: =COUNTIFS(STUDY03_DATA!C:C,A4,STUDY03_DATA!D:D,B4,STUDY03_DATA!F:F,C4)/'META DATA'!$B$2 -> 0.016666667 | F4: 0.05 | G4: =ABS($D4-F4) -> 0.033333333 | I4: 0.05 | J4: =ABS($D4-I4) -> 0.033333333 | L4: 0.05 | M4: =ABS($D4-L4) -> 0.033333333 | P4: 0 | Q4: =ABS($D4-P4) -> 0.016666667 | S4: 0 | T4: =ABS($D4-S4) -> 0.016666667 | V4: 0.15 | W4: =ABS($D4-V4) -> 0.13333333 | Y4: 0.05 | Z4: =ABS($D4-Y4) -> 0.033333333 | AB4: 0 | AC4: =ABS($D4-AB4) -> 0.016666667 | AE4: 0 | AF4: =ABS($D4-AE4) -> 0.016666667 | AH4: 0 | AI4: =ABS($D4-AH4) -> 0.016666667 | AK4: 0.1 | AL4: =ABS($D4-AK4) -> 0.083333333 | AN4: 0 | AO4: =ABS($D4-AN4) -> 0.016666667 | AQ4: 0.05 | AR4: =ABS($D4-AQ4) -> 0.033333333 | AT4: 0 | AU4: =ABS($D4-AT4) -> 0.016666667 | AW4: 0.1 | AX4: =ABS($D4-AW4) -> 0.083333333 | AZ4: 0 | BA4: =ABS($D4-AZ4) -> 0.016666667 | BC4: 0.1 | BD4: =ABS($D4-BC4) -> 0.083333333 | BF4: 0 | BG4: =ABS($D4-BF4) -> 0.016666667 | BJ4: Condition | BK4: State | BL4: Delta by State | BM4: Delta by Cond | BN4: Overall Delta
A5: GPT4 | B5: Waiting for Input | C5: Found Object | D5: =COUNTIFS(STUDY03_DATA!C:C,A5,STUDY03_DATA!D:D,B5,STUDY03_DATA!F:F,C5)/'META DATA'!$B$2 -> 0.016666667 | F5: 0 | G5: =ABS($D5-F5) -> 0.016666667 | I5: 0 | J5: =ABS($D5-I5) -> 0.016666667 | L5: 0 | M5: =ABS($D5-L5) -> 0.016666667 | P5: 0 | Q5: =ABS($D5-P5) -> 0.016666667 | S5: 0 | T5: =ABS($D5-S5) -> 0.016666667 | V5: 0 | W5: =ABS($D5-V5) -> 0.016666667 | Y5: 0 | Z5: =ABS($D5-Y5) -> 0.016666667 | AB5: 0 | AC5: =ABS($D5-AB5) -> 0.016666667 | AE5: 0 | AF5: =ABS($D5-AE5) -> 0.016666667 | AH5: 0 | AI5: =ABS($D5-AH5) -> 0.016666667 | AK5: 0 | AL5: =ABS($D5-AK5) -> 0.016666667 | AN5: 0 | AO5: =ABS($D5-AN5) -> 0.016666667 | AQ5: 0 | AR5: =ABS($D5-AQ5) -> 0.016666667 | AT5: 0 | AU5: =ABS($D5-AT5) -> 0.016666667 | AW5: 0 | AX5: =ABS($D5-AW5) -> 0.016666667 | AZ5: 0 | BA5: =ABS($D5-AZ5) -> 0.016666667 | BC5: 0 | BD5: =ABS($D5-BC5) -> 0.016666667 | BF5: 0 | BG5: =ABS($D5-BF5) -> 0.016666667 | BJ5: GPT4 | BK5: Waiting for Input | BL5: =AVERAGE(BA2:BA7) -> 0.076666667 | BM5: =AVERAGE(BL5:BL9) -> 0.097 | BN5: =AVERAGE(BM5,BM10,BM15) -> 0.096407407
A6: GPT4 | B6: Waiting for Input | C6: Needs Help | D6: =COUNTIFS(STUDY03_DATA!C:C,A6,STUDY03_DATA!D:D,B6,STUDY03_DATA!F:F,C6)/'META DATA'!$B$2 -> 0.05 | F6: 0 | G6: =ABS($D6-F6) -> 0.05 | I6: 0 | J6: =ABS($D6-I6) -> 0.05 | L6: 0 | M6: =ABS($D6-L6) -> 0.05 | P6: 0.1 | Q6: =ABS($D6-P6) -> 0.05 | S6: 0.05 | T6: =ABS($D6-S6) -> 0 | V6: 0.05 | W6: =ABS($D6-V6) -> 0 | Y6: 0.2 | Z6: =ABS($D6-Y6) -> 0.15 | AB6: 0 | AC6: =ABS($D6-AB6) -> 0.05 | AE6: 0 | AF6: =ABS($D6-AE6) -> 0.05 | AH6: 0 | AI6: =ABS($D6-AH6) -> 0.05 | AK6: 0.05 | AL6: =ABS($D6-AK6) -> 0 | AN6: 0.05 | AO6: =ABS($D6-AN6) -> 0 | AQ6: 0 | AR6: =ABS($D6-AQ6) -> 0.05 | AT6: 0 | AU6: =ABS($D6-AT6) -> 0.05 | AW6: 0 | AX6: =ABS($D6-AW6) -> 0.05 | AZ6: 0 | BA6: =ABS($D6-AZ6) -> 0.05 | BC6: 0 | BD6: =ABS($D6-BC6) -> 0.05 | BF6: 0 | BG6: =ABS($D6-BF6) -> 0.05 | BK6: Analyzing Object | BL6: =AVERAGE(BA8:BA13) -> 0.18888889
A7: GPT4 | B7: Waiting for Input | C7: Confused | D7: =COUNTIFS(STUDY03_DATA!C:C,A7,STUDY03_DATA!D:D,B7,STUDY03_DATA!F:F,C7)/'META DATA'!$B$2 -> 0.066666667 | F7: 0 | G7: =ABS($D7-F7) -> 0.066666667 | I7: 0 | J7: =ABS($D7-I7) -> 0.066666667 | L7: 0 | M7: =ABS($D7-L7) -> 0.066666667 | P7: 0 | Q7: =ABS($D7-P7) -> 0.066666667 | S7: 0.05 | T7: =ABS($D7-S7) -> 0.016666667 | V7: 0.1 | W7: =ABS($D7-V7) -> 0.033333333 | Y7: 0 | Z7: =ABS($D7-Y7) -> 0.066666667 | AB7: 0.05 | AC7: =ABS($D7-AB7) -> 0.016666667 | AE7: 0 | AF7: =ABS($D7-AE7) -> 0.066666667 | AH7: 0 | AI7: =ABS($D7-AH7) -> 0.066666667 | AK7: 0 | AL7: =ABS($D7-AK7) -> 0.066666667 | AN7: 0 | AO7: =ABS($D7-AN7) -> 0.066666667 | AQ7: 0 | AR7: =ABS($D7-AQ7) -> 0.066666667 | AT7: 0 | AU7: =ABS($D7-AT7) -> 0.066666667 | AW7: 0 | AX7: =ABS($D7-AW7) -> 0.066666667 | AZ7: 0 | BA7: =ABS($D7-AZ7) -> 0.066666667 | BC7: 0 | BD7: =ABS($D7-BC7) -> 0.066666667 | BF7: 0 | BG7: =ABS($D7-BF7) -> 0.066666667 | BK7: Found Object | BL7: =AVERAGE(BA14:BA19) -> 0.10833333
A8: GPT4 | B8: Waiting for Input | C8: None | D8: =COUNTIFS(STUDY03_DATA!C:C,A8,STUDY03_DATA!D:D,B8,STUDY03_DATA!F:F,C8)/'META DATA'!$B$2 -> 0.11666667 | F8: 0.25 | G8: =ABS($D8-F8) -> 0.13333333 | I8: 0.25 | J8: =ABS($D8-I8) -> 0.13333333 | L8: 0.2 | M8: =ABS($D8-L8) -> 0.083333333 | P8: 0.1 | Q8: =ABS($D8-P8) -> 0.016666667 | S8: 0 | T8: =ABS($D8-S8) -> 0.11666667 | V8: 0.4 | W8: =ABS($D8-V8) -> 0.28333333 | Y8: 0.55 | Z8: =ABS($D8-Y8) -> 0.43333333 | AB8: 0.75 | AC8: =ABS($D8-AB8) -> 0.63333333 | AE8: 0.1 | AF8: =ABS($D8-AE8) -> 0.016666667 | AH8: 0.05 | AI8: =ABS($D8-AH8) -> 0.066666667 | AK8: 0.4 | AL8: =ABS($D8-AK8) -> 0.28333333 | AN8: 0.35 | AO8: =ABS($D8-AN8) -> 0.23333333 | AQ8: 0.85 | AR8: =ABS($D8-AQ8) -> 0.73333333 | AT8: 0.05 | AU8: =ABS($D8-AT8) -> 0.066666667 | AW8: 0.05 | AX8: =ABS($D8-AW8) -> 0.066666667 | AZ8: 0.5 | BA8: =ABS($D8-AZ8) -> 0.38333333 | BC8: 0.3 | BD8: =ABS($D8-BC8) -> 0.18333333 | BF8: 0.9 | BG8: =ABS($D8-BF8) -> 0.78333333 | BK8: Needs Help | BL8: =AVERAGE(BA20:BA25) -> 0.030555556
A9: GPT4 | B9: Analyzing Object | C9: Waiting for Input | D9: =COUNTIFS(STUDY03_DATA!C:C,A9,STUDY03_DATA!D:D,B9,STUDY03_DATA!F:F,C9)/'META DATA'!$B$2 -> 0.083333333 | F9: {=LLM_AO_14!S2:S7} -> 0.2 | G9: =ABS($D9-F9) -> 0.11666667 | I9: {=LLM_AO_18!S2:S7} -> 0.2 | J9: =ABS($D9-I9) -> 0.11666667 | L9: {=LLM_AO_19!S2:S7} -> 0.35 | M9: =ABS($D9-L9) -> 0.26666667 | P9: {=LLM_AO_20!S2:S7} -> 0.1 | Q9: =ABS($D9-P9) -> 0.016666667 | S9: {=LLM_AO_21!S2:S7} -> 0.15 | T9: =ABS($D9-S9) -> 0.066666667 | V9: {=LLM_AO_22!S2:S7} -> 0.35 | W9: =ABS($D9-V9) -> 0.26666667 | Y9: {=LLM_AO_23!S2:S7} -> 0.25 | Z9: =ABS($D9-Y9) -> 0.16666667 | AB9: {=LLM_AO_24!S2:S7} -> 0 | AC9: =ABS($D9-AB9) -> 0.083333333 | AE9: {=LLM_AO_24!S2:S7} -> 0 | AF9: =ABS($D9-AE9) -> 0.083333333 | AH9: {=LLM_AO_26!S2:S7} -> 0.1 | AI9: =ABS($D9-AH9) -> 0.016666667 | AK9: {=LLM_AO_27!S2:S7} -> 0.3 | AL9: =ABS($D9-AK9) -> 0.21666667 | AN9: {=LLM_AO_28!S2:S7} -> 0.1 | AO9: =ABS($D9-AN9) -> 0.016666667 | AQ9: {=LLM_AO_29!S2:S7} -> 0 | AR9: =ABS($D9-AQ9) -> 0.083333333 | AT9: {=LLM_AO_30!S2:S7} -> 0.05 | AU9: =ABS($D9-AT9) -> 0.033333333 | AW9: {=LLM_AO_31!S2:S7} -> 0.3 | AX9: =ABS($D9-AW9) -> 0.21666667 | AZ9: {=LLM_AO_32!S2:S7} -> 0.2 | BA9: =ABS($D9-AZ9) -> 0.11666667 | BC9: {=LLM_AO_33!S2:S7} -> 0.25 | BD9: =ABS($D9-BC9) -> 0.16666667 | BF9: {=LLM_AO_34!S2:S7} -> 0.1 | BG9: =ABS($D9-BF9) -> 0.016666667 | BK9: Confused | BL9: =AVERAGE(BA26:BA31) -> 0.080555556
A10: GPT4 | B10: Analyzing Object | C10: Analyzing Object | D10: =COUNTIFS(STUDY03_DATA!C:C,A10,STUDY03_DATA!D:D,B10,STUDY03_DATA!F:F,C10)/'META DATA'!$B$2 -> 0.33333333 | F10: 0.45 | G10: =ABS($D10-F10) -> 0.11666667 | I10: 0.4 | J10: =ABS($D10-I10) -> 0.066666667 | L10: 0.35 | M10: =ABS($D10-L10) -> 0.016666667 | P10: 0.9 | Q10: =ABS($D10-P10) -> 0.56666667 | S10: 0.65 | T10: =ABS($D10-S10) -> 0.31666667 | V10: 0.35 | W10: =ABS($D10-V10) -> 0.016666667 | Y10: 0.15 | Z10: =ABS($D10-Y10) -> 0.18333333 | AB10: 0.05 | AC10: =ABS($D10-AB10) -> 0.28333333 | AE10: 0.05 | AF10: =ABS($D10-AE10) -> 0.28333333 | AH10: 0.7 | AI10: =ABS($D10-AH10) -> 0.36666667 | AK10: 0.25 | AL10: =ABS($D10-AK10) -> 0.083333333 | AN10: 0.3 | AO10: =ABS($D10-AN10) -> 0.033333333 | AQ10: 0.15 | AR10: =ABS($D10-AQ10) -> 0.18333333 | AT10: 0.95 | AU10: =ABS($D10-AT10) -> 0.61666667 | AW10: 0.6 | AX10: =ABS($D10-AW10) -> 0.26666667 | AZ10: 0.5 | BA10: =ABS($D10-AZ10) -> 0.16666667 | BC10: 0.25 | BD10: =ABS($D10-BC10) -> 0.083333333 | BF10: 0 | BG10: =ABS($D10-BF10) -> 0.33333333 | BJ10: Human | BK10: Waiting for Input | BL10: =AVERAGE(BA32:BA37) -> 0.055555556 | BM10: =AVERAGE(BL10:BL14) -> 0.10888889
A11: GPT4 | B11: Analyzing Object | C11: Found Object | D11: =COUNTIFS(STUDY03_DATA!C:C,A11,STUDY03_DATA!D:D,B11,STUDY03_DATA!F:F,C11)/'META DATA'!$B$2 -> 0.5 | F11: 0.15 | G11: =ABS($D11-F11) -> 0.35 | I11: 0.3 | J11: =ABS($D11-I11) -> 0.2 | L11: 0.15 | M11: =ABS($D11-L11) -> 0.35 | P11: 0 | Q11: =ABS($D11-P11) -> 0.5 | S11: 0.15 | T11: =ABS($D11-S11) -> 0.35 | V11: 0.15 | W11: =ABS($D11-V11) -> 0.35 | Y11: 0.1 | Z11: =ABS($D11-Y11) -> 0.4 | AB11: 0 | AC11: =ABS($D11-AB11) -> 0.5 | AE11: 0 | AF11: =ABS($D11-AE11) -> 0.5 | AH11: 0.05 | AI11: =ABS($D11-AH11) -> 0.45 | AK11: 0.1 | AL11: =ABS($D11-AK11) -> 0.4 | AN11: 0.15 | AO11: =ABS($D11-AN11) -> 0.35 | AQ11: 0 | AR11: =ABS($D11-AQ11) -> 0.5 | AT11: 0 | AU11: =ABS($D11-AT11) -> 0.5 | AW11: 0.1 | AX11: =ABS($D11-AW11) -> 0.4 | AZ11: 0.1 | BA11: =ABS($D11-AZ11) -> 0.4 | BC11: 0.05 | BD11: =ABS($D11-BC11) -> 0.45 | BF11: 0.05 | BG11: =ABS($D11-BF11) -> 0.45 | BK11: Analyzing Object | BL11: =AVERAGE(BA38:BA43) -> 0.13055556
A12: GPT4 | B12: Analyzing Object | C12: Needs Help | D12: =COUNTIFS(STUDY03_DATA!C:C,A12,STUDY03_DATA!D:D,B12,STUDY03_DATA!F:F,C12)/'META DATA'!$B$2 -> 0.033333333 | F12: 0 | G12: =ABS($D12-F12) -> 0.033333333 | I12: 0 | J12: =ABS($D12-I12) -> 0.033333333 | L12: 0 | M12: =ABS($D12-L12) -> 0.033333333 | P12: 0 | Q12: =ABS($D12-P12) -> 0.033333333 | S12: 0 | T12: =ABS($D12-S12) -> 0.033333333 | V12: 0 | W12: =ABS($D12-V12) -> 0.033333333 | Y12: 0 | Z12: =ABS($D12-Y12) -> 0.033333333 | AB12: 0 | AC12: =ABS($D12-AB12) -> 0.033333333 | AE12: 0 | AF12: =ABS($D12-AE12) -> 0.033333333 | AH12: 0 | AI12: =ABS($D12-AH12) -> 0.033333333 | AK12: 0 | AL12: =ABS($D12-AK12) -> 0.033333333 | AN12: 0 | AO12: =ABS($D12-AN12) -> 0.033333333 | AQ12: 0 | AR12: =ABS($D12-AQ12) -> 0.033333333 | AT12: 0 | AU12: =ABS($D12-AT12) -> 0.033333333 | AW12: 0 | AX12: =ABS($D12-AW12) -> 0.033333333 | AZ12: 0 | BA12: =ABS($D12-AZ12) -> 0.033333333 | BC12: 0 | BD12: =ABS($D12-BC12) -> 0.033333333 | BF12: 0 | BG12: =ABS($D12-BF12) -> 0.033333333 | BK12: Found Object | BL12: =AVERAGE(BA44:BA49) -> 0.066666667
A13: GPT4 | B13: Analyzing Object | C13: Confused | D13: =COUNTIFS(STUDY03_DATA!C:C,A13,STUDY03_DATA!D:D,B13,STUDY03_DATA!F:F,C13)/'META DATA'!$B$2 -> 0.033333333 | F13: 0 | G13: =ABS($D13-F13) -> 0.033333333 | I13: 0 | J13: =ABS($D13-I13) -> 0.033333333 | L13: 0 | M13: =ABS($D13-L13) -> 0.033333333 | P13: 0 | Q13: =ABS($D13-P13) -> 0.033333333 | S13: 0 | T13: =ABS($D13-S13) -> 0.033333333 | V13: 0 | W13: =ABS($D13-V13) -> 0.033333333 | Y13: 0 | Z13: =ABS($D13-Y13) -> 0.033333333 | AB13: 0 | AC13: =ABS($D13-AB13) -> 0.033333333 | AE13: 0 | AF13: =ABS($D13-AE13) -> 0.033333333 | AH13: 0 | AI13: =ABS($D13-AH13) -> 0.033333333 | AK13: 0 | AL13: =ABS($D13-AK13) -> 0.033333333 | AN13: 0 | AO13: =ABS($D13-AN13) -> 0.033333333 | AQ13: 0 | AR13: =ABS($D13-AQ13) -> 0.033333333 | AT13: 0 | AU13: =ABS($D13-AT13) -> 0.033333333 | AW13: 0 | AX13: =ABS($D13-AW13) -> 0.033333333 | AZ13: 0 | BA13: =ABS($D13-AZ13) -> 0.033333333 | BC13: 0 | BD13: =ABS($D13-BC13) -> 0.033333333 | BF13: 0 | BG13: =ABS($D13-BF13) -> 0.033333333 | BK13: Needs Help | BL13: =AVERAGE(BA50:BA55) -> 0.21666667
A14: GPT4 | B14: Analyzing Object | C14: None | D14: =COUNTIFS(STUDY03_DATA!C:C,A14,STUDY03_DATA!D:D,B14,STUDY03_DATA!F:F,C14)/'META DATA'!$B$2 -> 0.016666667 | F14: 0.15 | G14: =ABS($D14-F14) -> 0.13333333 | I14: 0.1 | J14: =ABS($D14-I14) -> 0.083333333 | L14: 0.15 | M14: =ABS($D14-L14) -> 0.13333333 | P14: 0 | Q14: =ABS($D14-P14) -> 0.016666667 | S14: 0.05 | T14: =ABS($D14-S14) -> 0.033333333 | V14: 0.15 | W14: =ABS($D14-V14) -> 0.13333333 | Y14: 0.5 | Z14: =ABS($D14-Y14) -> 0.48333333 | AB14: 0.95 | AC14: =ABS($D14-AB14) -> 0.93333333 | AE14: 0.95 | AF14: =ABS($D14-AE14) -> 0.93333333 | AH14: 0.15 | AI14: =ABS($D14-AH14) -> 0.13333333 | AK14: 0.3 | AL14: =ABS($D14-AK14) -> 0.28333333 | AN14: 0.45 | AO14: =ABS($D14-AN14) -> 0.43333333 | AQ14: 0.85 | AR14: =ABS($D14-AQ14) -> 0.83333333 | AT14: 0 | AU14: =ABS($D14-AT14) -> 0.016666667 | AW14: 0 | AX14: =ABS($D14-AW14) -> 0.016666667 | AZ14: 0.2 | BA14: =ABS($D14-AZ14) -> 0.18333333 | BC14: 0.4 | BD14: =ABS($D14-BC14) -> 0.38333333 | BF14: 0.85 | BG14: =ABS($D14-BF14) -> 0.83333333 | BK14: Confused | BL14: =AVERAGE(BA56:BA61) -> 0.075
A15: GPT4 | B15: Found Object | C15: Waiting for Input | D15: =COUNTIFS(STUDY03_DATA!C:C,A15,STUDY03_DATA!D:D,B15,STUDY03_DATA!F:F,C15)/'META DATA'!$B$2 -> 0.016666667 | F15: {=LLM_FO_14!S2:S7} -> 0.05 | G15: =ABS($D15-F15) -> 0.033333333 | I15: {=LLM_FO_18!S2:S7} -> 0 | J15: =ABS($D15-I15) -> 0.016666667 | L15: {=LLM_FO_18!S2:S7} -> 0 | M15: =ABS($D15-L15) -> 0.016666667 | P15: {=LLM_FO_20!S2:S7} -> 0 | Q15: =ABS($D15-P15) -> 0.016666667 | S15: {=LLM_FO_21!S2:S7} -> 0 | T15: =ABS($D15-S15) -> 0.016666667 | V15: {=LLM_FO_22!S2:S7} -> 0 | W15: =ABS($D15-V15) -> 0.016666667 | Y15: {=LLM_FO_23!S2:S7} -> 0.15 | Z15: =ABS($D15-Y15) -> 0.13333333 | AB15: {=LLM_FO_24!S2:S7} -> 0 | AC15: =ABS($D15-AB15) -> 0.016666667 | AE15: {=LLM_FO_25!S2:S7} -> 0 | AF15: =ABS($D15-AE15) -> 0.016666667 | AH15: {=LLM_FO_26!S2:S7} -> 0 | AI15: =ABS($D15-AH15) -> 0.016666667 | AK15: {=LLM_FO_27!S2:S7} -> 0 | AL15: =ABS($D15-AK15) -> 0.016666667 | AN15: {=LLM_FO_28!S2:S7} -> 0 | AO15: =ABS($D15-AN15) -> 0.016666667 | AQ15: {=LLM_FO_29!S2:S7} -> 0 | AR15: =ABS($D15-AQ15) -> 0.016666667 | AT15: {=LLM_FO_30!S2:S7} -> 0 | AU15: =ABS($D15-AT15) -> 0.016666667 | AW15: {=LLM_FO_31!S2:S7} -> 0 | AX15: =ABS($D15-AW15) -> 0.016666667 | AZ15: {=LLM_FO_32!S2:S7} -> 0.05 | BA15: =ABS($D15-AZ15) -> 0.033333333 | BC15: {=LLM_FO_33!S2:S7} -> 0 | BD15: =ABS($D15-BC15) -> 0.016666667 | BF15: {=LLM_FO_34!S2:S7} -> 0 | BG15: =ABS($D15-BF15) -> 0.016666667 | BJ15: Random | BK15: Waiting for Input | BL15: =AVERAGE(BA62:BA67) -> 0.11388889 | BM15: =AVERAGE(BL15:BL19) -> 0.083333333
A16: GPT4 | B16: Found Object | C16: Analyzing Object | D16: =COUNTIFS(STUDY03_DATA!C:C,A16,STUDY03_DATA!D:D,B16,STUDY03_DATA!F:F,C16)/'META DATA'!$B$2 -> 0.56666667 | F16: 0.7 | G16: =ABS($D16-F16) -> 0.13333333 | I16: 0.7 | J16: =ABS($D16-I16) -> 0.13333333 | L16: 0.7 | M16: =ABS($D16-L16) -> 0.13333333 | P16: 1 | Q16: =ABS($D16-P16) -> 0.43333333 | S16: 0.8 | T16: =ABS($D16-S16) -> 0.23333333 | V16: 0.75 | W16: =ABS($D16-V16) -> 0.18333333 | Y16: 0.35 | Z16: =ABS($D16-Y16) -> 0.21666667 | AB16: 0.25 | AC16: =ABS($D16-AB16) -> 0.31666667 | AE16: 0.9 | AF16: =ABS($D16-AE16) -> 0.33333333 | AH16: 0.65 | AI16: =ABS($D16-AH16) -> 0.083333333 | AK16: 0.55 | AL16: =ABS($D16-AK16) -> 0.016666667 | AN16: 0.3 | AO16: =ABS($D16-AN16) -> 0.26666667 | AQ16: 0.1 | AR16: =ABS($D16-AQ16) -> 0.46666667 | AT16: 0.95 | AU16: =ABS($D16-AT16) -> 0.38333333 | AW16: 0.95 | AX16: =ABS($D16-AW16) -> 0.38333333 | AZ16: 0.75 | BA16: =ABS($D16-AZ16) -> 0.18333333 | BC16: 0.45 | BD16: =ABS($D16-BC16) -> 0.11666667 | BF16: 0.1 | BG16: =ABS($D16-BF16) -> 0.46666667 | BK16: Analyzing Object | BL16: =AVERAGE(BA68:BA73) -> 0.038888889
A17: GPT4 | B17: Found Object | C17: Found Object | D17: =COUNTIFS(STUDY03_DATA!C:C,A17,STUDY03_DATA!D:D,B17,STUDY03_DATA!F:F,C17)/'META DATA'!$B$2 -> 0.4 | F17: 0.2 | G17: =ABS($D17-F17) -> 0.2 | I17: 0.2 | J17: =ABS($D17-I17) -> 0.2 | L17: 0.2 | M17: =ABS($D17-L17) -> 0.2 | P17: 0 | Q17: =ABS($D17-P17) -> 0.4 | S17: 0.15 | T17: =ABS($D17-S17) -> 0.25 | V17: 0.05 | W17: =ABS($D17-V17) -> 0.35 | Y17: 0.25 | Z17: =ABS($D17-Y17) -> 0.15 | AB17: 0.1 | AC17: =ABS($D17-AB17) -> 0.3 | AE17: 0.1 | AF17: =ABS($D17-AE17) -> 0.3 | AH17: 0.35 | AI17: =ABS($D17-AH17) -> 0.05 | AK17: 0.2 | AL17: =ABS($D17-AK17) -> 0.2 | AN17: 0.2 | AO17: =ABS($D17-AN17) -> 0.2 | AQ17: 0 | AR17: =ABS($D17-AQ17) -> 0.4 | AT17: 0.05 | AU17: =ABS($D17-AT17) -> 0.35 | AW17: 0.05 | AX17: =ABS($D17-AW17) -> 0.35 | AZ17: 0.15 | BA17: =ABS($D17-AZ17) -> 0.25 | BC17: 0.1 | BD17: =ABS($D17-BC17) -> 0.3 | BF17: 0.05 | BG17: =ABS($D17-BF17) -> 0.35 | BK17: Found Object | BL17: =AVERAGE(BA74:BA79) -> 0.072222222
A18: GPT4 | B18: Found Object | C18: Needs Help | D18: =COUNTIFS(STUDY03_DATA!C:C,A18,STUDY03_DATA!D:D,B18,STUDY03_DATA!F:F,C18)/'META DATA'!$B$2 -> 0 | F18: 0 | G18: =ABS($D18-F18) -> 0 | I18: 0 | J18: =ABS($D18-I18) -> 0 | L18: 0 | M18: =ABS($D18-L18) -> 0 | P18: 0 | Q18: =ABS($D18-P18) -> 0 | S18: 0 | T18: =ABS($D18-S18) -> 0 | V18: 0.05 | W18: =ABS($D18-V18) -> 0.05 | Y18: 0 | Z18: =ABS($D18-Y18) -> 0 | AB18: 0 | AC18: =ABS($D18-AB18) -> 0 | AE18: 0 | AF18: =ABS($D18-AE18) -> 0 | AH18: 0 | AI18: =ABS($D18-AH18) -> 0 | AK18: 0 | AL18: =ABS($D18-AK18) -> 0 | AN18: 0 | AO18: =ABS($D18-AN18) -> 0 | AQ18: 0.05 | AR18: =ABS($D18-AQ18) -> 0.05 | AT18: 0 | AU18: =ABS($D18-AT18) -> 0 | AW18: 0 | AX18: =ABS($D18-AW18) -> 0 | AZ18: 0 | BA18: =ABS($D18-AZ18) -> 0 | BC18: 0 | BD18: =ABS($D18-BC18) -> 0 | BF18: 0 | BG18: =ABS($D18-BF18) -> 0 | BK18: Needs Help | BL18: =AVERAGE(BA80:BA85) -> 0.10833333
A19: GPT4 | B19: Found Object | C19: Confused | D19: =COUNTIFS(STUDY03_DATA!C:C,A19,STUDY03_DATA!D:D,B19,STUDY03_DATA!F:F,C19)/'META DATA'!$B$2 -> 0 | F19: 0 | G19: =ABS($D19-F19) -> 0 | I19: 0 | J19: =ABS($D19-I19) -> 0 | L19: 0 | M19: =ABS($D19-L19) -> 0 | P19: 0 | Q19: =ABS($D19-P19) -> 0 | S19: 0 | T19: =ABS($D19-S19) -> 0 | V19: 0 | W19: =ABS($D19-V19) -> 0 | Y19: 0 | Z19: =ABS($D19-Y19) -> 0 | AB19: 0 | AC19: =ABS($D19-AB19) -> 0 | AE19: 0 | AF19: =ABS($D19-AE19) -> 0 | AH19: 0 | AI19: =ABS($D19-AH19) -> 0 | AK19: 0 | AL19: =ABS($D19-AK19) -> 0 | AN19: 0 | AO19: =ABS($D19-AN19) -> 0 | AQ19: 0 | AR19: =ABS($D19-AQ19) -> 0 | AT19: 0 | AU19: =ABS($D19-AT19) -> 0 | AW19: 0 | AX19: =ABS($D19-AW19) -> 0 | AZ19: 0 | BA19: =ABS($D19-AZ19) -> 0 | BC19: 0 | BD19: =ABS($D19-BC19) -> 0 | BF19: 0 | BG19: =ABS($D19-BF19) -> 0 | BK19: Confused | BL19: =AVERAGE(BA86:BA91) -> 0.083333333
A20: GPT4 | B20: Found Object | C20: None | D20: =COUNTIFS(STUDY03_DATA!C:C,A20,STUDY03_DATA!D:D,B20,STUDY03_DATA!F:F,C20)/'META DATA'!$B$2 -> 0.016666667 | F20: 0.05 | G20: =ABS($D20-F20) -> 0.033333333 | I20: 0.1 | J20: =ABS($D20-I20) -> 0.083333333 | L20: 0.1 | M20: =ABS($D20-L20) -> 0.083333333 | P20: 0 | Q20: =ABS($D20-P20) -> 0.016666667 | S20: 0.05 | T20: =ABS($D20-S20) -> 0.033333333 | V20: 0.15 | W20: =ABS($D20-V20) -> 0.13333333 | Y20: 0.25 | Z20: =ABS($D20-Y20) -> 0.23333333 | AB20: 0.65 | AC20: =ABS($D20-AB20) -> 0.63333333 | AE20: 0 | AF20: =ABS($D20-AE20) -> 0.016666667 | AH20: 0 | AI20: =ABS($D20-AH20) -> 0.016666667 | AK20: 0.25 | AL20: =ABS($D20-AK20) -> 0.23333333 | AN20: 0.5 | AO20: =ABS($D20-AN20) -> 0.48333333 | AQ20: 0.85 | AR20: =ABS($D20-AQ20) -> 0.83333333 | AT20: 0 | AU20: =ABS($D20-AT20) -> 0.016666667 | AW20: 0 | AX20: =ABS($D20-AW20) -> 0.016666667 | AZ20: 0.05 | BA20: =ABS($D20-AZ20) -> 0.033333333 | BC20: 0.45 | BD20: =ABS($D20-BC20) -> 0.43333333 | BF20: 0.85 | BG20: =ABS($D20-BF20) -> 0.83333333
A21: GPT4 | B21: Needs Help | C21: Waiting for Input | D21: =COUNTIFS(STUDY03_DATA!C:C,A21,STUDY03_DATA!D:D,B21,STUDY03_DATA!F:F,C21)/'META DATA'!$B$2 -> 0.15 | F21: {=LLM_NH_14!S2:S7} -> 0.15 | G21: =ABS($D21-F21) -> 0 | I21: {=LLM_NH_18!S2:S7} -> 0.15 | J21: =ABS($D21-I21) -> 0 | L21: {=LLM_NH_19!S2:S7} -> 0.05 | M21: =ABS($D21-L21) -> 0.1 | P21: {=LLM_NH_20!S2:S7} -> 0 | Q21: =ABS($D21-P21) -> 0.15 | S21: {=LLM_NH_21!S2:S7} -> 0.1 | T21: =ABS($D21-S21) -> 0.05 | V21: {=LLM_NH_22!S2:S7} -> 0.15 | W21: =ABS($D21-V21) -> 0 | Y21: {=LLM_NH_23!S2:S7} -> 0.2 | Z21: =ABS($D21-Y21) -> 0.05 | AB21: {=LLM_NH_24!S2:S7} -> 0 | AC21: =ABS($D21-AB21) -> 0.15 | AE21: {=LLM_NH_25!S2:S7} -> 0 | AF21: =ABS($D21-AE21) -> 0.15 | AH21: {=LLM_NH_26!S2:S7} -> 0 | AI21: =ABS($D21-AH21) -> 0.15 | AK21: {=LLM_NH_27!S2:S7} -> 0.05 | AL21: =ABS($D21-AK21) -> 0.1 | AN21: {=LLM_NH_28!S2:S7} -> 0.15 | AO21: =ABS($D21-AN21) -> 0 | AQ21: {=LLM_NH_29!S2:S7} -> 0.25 | AR21: =ABS($D21-AQ21) -> 0.1 | AT21: {=LLM_NH_30!S2:S7} -> 0 | AU21: =ABS($D21-AT21) -> 0.15 | AW21: {=LLM_NH_31!S2:S7} -> 0.05 | AX21: =ABS($D21-AW21) -> 0.1 | AZ21: {=LLM_NH_32!S2:S7} -> 0.1 | BA21: =ABS($D21-AZ21) -> 0.05 | BC21: {=LLM_NH_33!S2:S7} -> 0.2 | BD21: =ABS($D21-BC21) -> 0.05 | BF21: {=LLM_NH_34!S2:S7} -> 0.05 | BG21: =ABS($D21-BF21) -> 0.1
A22: GPT4 | B22: Needs Help | C22: Analyzing Object | D22: =COUNTIFS(STUDY03_DATA!C:C,A22,STUDY03_DATA!D:D,B22,STUDY03_DATA!F:F,C22)/'META DATA'!$B$2 -> 0.1 | F22: 0.05 | G22: =ABS($D22-F22) -> 0.05 | I22: 0 | J22: =ABS($D22-I22) -> 0.1 | L22: 0.15 | M22: =ABS($D22-L22) -> 0.05 | P22: 0 | Q22: =ABS($D22-P22) -> 0.1 | S22: 0.05 | T22: =ABS($D22-S22) -> 0.05 | V22: 0.05 | W22: =ABS($D22-V22) -> 0.05 | Y22: 0.05 | Z22: =ABS($D22-Y22) -> 0.05 | AB22: 0 | AC22: =ABS($D22-AB22) -> 0.1 | AE22: 0 | AF22: =ABS($D22-AE22) -> 0.1 | AH22: 0 | AI22: =ABS($D22-AH22) -> 0.1 | AK22: 0.05 | AL22: =ABS($D22-AK22) -> 0.05 | AN22: 0.05 | AO22: =ABS($D22-AN22) -> 0.05 | AQ22: 0.05 | AR22: =ABS($D22-AQ22) -> 0.05 | AT22: 0.05 | AU22: =ABS($D22-AT22) -> 0.05 | AW22: 0 | AX22: =ABS($D22-AW22) -> 0.1 | AZ22: 0.1 | BA22: =ABS($D22-AZ22) -> 0 | BC22: 0.1 | BD22: =ABS($D22-BC22) -> 0 | BF22: 0.1 | BG22: =ABS($D22-BF22) -> 0 | BJ22: ACCURACY PROXY VALIDATION DATA (MEAN ABS ALIGNMENT = MAA = 1 - MAE) | ID 32
A23: GPT4 | B23: Needs Help | C23: Found Object | D23: =COUNTIFS(STUDY03_DATA!C:C,A23,STUDY03_DATA!D:D,B23,STUDY03_DATA!F:F,C23)/'META DATA'!$B$2 -> 0.033333333 | F23: 0 | G23: =ABS($D23-F23) -> 0.033333333 | I23: 0 | J23: =ABS($D23-I23) -> 0.033333333 | L23: 0 | M23: =ABS($D23-L23) -> 0.033333333 | P23: 0 | Q23: =ABS($D23-P23) -> 0.033333333 | S23: 0 | T23: =ABS($D23-S23) -> 0.033333333 | V23: 0 | W23: =ABS($D23-V23) -> 0.033333333 | Y23: 0.05 | Z23: =ABS($D23-Y23) -> 0.016666667 | AB23: 0 | AC23: =ABS($D23-AB23) -> 0.033333333 | AE23: 0 | AF23: =ABS($D23-AE23) -> 0.033333333 | AH23: 0 | AI23: =ABS($D23-AH23) -> 0.033333333 | AK23: 0 | AL23: =ABS($D23-AK23) -> 0.033333333 | AN23: 0 | AO23: =ABS($D23-AN23) -> 0.033333333 | AQ23: 0 | AR23: =ABS($D23-AQ23) -> 0.033333333 | AT23: 0 | AU23: =ABS($D23-AT23) -> 0.033333333 | AW23: 0 | AX23: =ABS($D23-AW23) -> 0.033333333 | AZ23: 0 | BA23: =ABS($D23-AZ23) -> 0.033333333 | BC23: 0 | BD23: =ABS($D23-BC23) -> 0.033333333 | BF23: 0 | BG23: =ABS($D23-BF23) -> 0.033333333 | BJ23: Condition | BK23: State | BL23: Alignment by State | BM23: Alignment by Cond | BN23: Overall Alignment
A24: GPT4 | B24: Needs Help | C24: Needs Help | D24: =COUNTIFS(STUDY03_DATA!C:C,A24,STUDY03_DATA!D:D,B24,STUDY03_DATA!F:F,C24)/'META DATA'!$B$2 -> 0.51666667 | F24: 0.45 | G24: =ABS($D24-F24) -> 0.066666667 | I24: 0.4 | J24: =ABS($D24-I24) -> 0.11666667 | L24: 0.45 | M24: =ABS($D24-L24) -> 0.066666667 | P24: 0.75 | Q24: =ABS($D24-P24) -> 0.23333333 | S24: 0.45 | T24: =ABS($D24-S24) -> 0.066666667 | V24: 0.6 | W24: =ABS($D24-V24) -> 0.083333333 | Y24: 0.05 | Z24: =ABS($D24-Y24) -> 0.46666667 | AB24: 0.1 | AC24: =ABS($D24-AB24) -> 0.41666667 | AE24: 0.95 | AF24: =ABS($D24-AE24) -> 0.43333333 | AH24: 0.75 | AI24: =ABS($D24-AH24) -> 0.23333333 | AK24: 0.5 | AL24: =ABS($D24-AK24) -> 0.016666667 | AN24: 0.2 | AO24: =ABS($D24-AN24) -> 0.31666667 | AQ24: 0.15 | AR24: =ABS($D24-AQ24) -> 0.36666667 | AT24: 0.85 | AU24: =ABS($D24-AT24) -> 0.33333333 | AW24: 0.8 | AX24: =ABS($D24-AW24) -> 0.28333333 | AZ24: 0.55 | BA24: =ABS($D24-AZ24) -> 0.033333333 | BC24: 0.3 | BD24: =ABS($D24-BC24) -> 0.21666667 | BF24: 0 | BG24: =ABS($D24-BF24) -> 0.51666667 | BJ24: GPT4 | BK24: Waiting for Input | BL24: =1-BL5 -> 0.92333333 | BM24: =AVERAGE(BL24:BL28) -> 0.903 | BN24: =AVERAGE(BM24,BM29,BM34) -> 0.90359259
A25: GPT4 | B25: Needs Help | C25: Confused | D25: =COUNTIFS(STUDY03_DATA!C:C,A25,STUDY03_DATA!D:D,B25,STUDY03_DATA!F:F,C25)/'META DATA'!$B$2 -> 0.11666667 | F25: 0.3 | G25: =ABS($D25-F25) -> 0.18333333 | I25: 0.4 | J25: =ABS($D25-I25) -> 0.28333333 | L25: 0.35 | M25: =ABS($D25-L25) -> 0.23333333 | P25: 0.25 | Q25: =ABS($D25-P25) -> 0.13333333 | S25: 0.4 | T25: =ABS($D25-S25) -> 0.28333333 | V25: 0.15 | W25: =ABS($D25-V25) -> 0.033333333 | Y25: 0.35 | Z25: =ABS($D25-Y25) -> 0.23333333 | AB25: 0.15 | AC25: =ABS($D25-AB25) -> 0.033333333 | AE25: 0.05 | AF25: =ABS($D25-AE25) -> 0.066666667 | AH25: 0.2 | AI25: =ABS($D25-AH25) -> 0.083333333 | AK25: 0.35 | AL25: =ABS($D25-AK25) -> 0.23333333 | AN25: 0.35 | AO25: =ABS($D25-AN25) -> 0.23333333 | AQ25: 0.1 | AR25: =ABS($D25-AQ25) -> 0.016666667 | AT25: 0.1 | AU25: =ABS($D25-AT25) -> 0.016666667 | AW25: 0.15 | AX25: =ABS($D25-AW25) -> 0.033333333 | AZ25: 0.15 | BA25: =ABS($D25-AZ25) -> 0.033333333 | BC25: 0.1 | BD25: =ABS($D25-BC25) -> 0.016666667 | BF25: 0.05 | BG25: =ABS($D25-BF25) -> 0.066666667 | BK25: Analyzing Object | BL25: =1-BL6 -> 0.81111111
A26: GPT4 | B26: Needs Help | C26: None | D26: =COUNTIFS(STUDY03_DATA!C:C,A26,STUDY03_DATA!D:D,B26,STUDY03_DATA!F:F,C26)/'META DATA'!$B$2 -> 0.083333333 | F26: 0.05 | G26: =ABS($D26-F26) -> 0.033333333 | I26: 0.05 | J26: =ABS($D26-I26) -> 0.033333333 | L26: 0 | M26: =ABS($D26-L26) -> 0.083333333 | P26: 0 | Q26: =ABS($D26-P26) -> 0.083333333 | S26: 0 | T26: =ABS($D26-S26) -> 0.083333333 | V26: 0.05 | W26: =ABS($D26-V26) -> 0.033333333 | Y26: 0.3 | Z26: =ABS($D26-Y26) -> 0.21666667 | AB26: 0.7 | AC26: =ABS($D26-AB26) -> 0.61666667 | AE26: 0 | AF26: =ABS($D26-AE26) -> 0.083333333 | AH26: 0 | AI26: =ABS($D26-AH26) -> 0.083333333 | AK26: 0.05 | AL26: =ABS($D26-AK26) -> 0.033333333 | AN26: 0.15 | AO26: =ABS($D26-AN26) -> 0.066666667 | AQ26: 0.4 | AR26: =ABS($D26-AQ26) -> 0.31666667 | AT26: 0 | AU26: =ABS($D26-AT26) -> 0.083333333 | AW26: 0 | AX26: =ABS($D26-AW26) -> 0.083333333 | AZ26: 0.1 | BA26: =ABS($D26-AZ26) -> 0.016666667 | BC26: 0.3 | BD26: =ABS($D26-BC26) -> 0.21666667 | BF26: 0.8 | BG26: =ABS($D26-BF26) -> 0.71666667 | BK26: Found Object | BL26: =1-BL7 -> 0.89166667
A27: GPT4 | B27: Confused | C27: Waiting for Input | D27: =COUNTIFS(STUDY03_DATA!C:C,A27,STUDY03_DATA!D:D,B27,STUDY03_DATA!F:F,C27)/'META DATA'!$B$2 -> 0.05 | F27: {=LLM_C_14!S2:S7} -> 0.2 | G27: =ABS($D27-F27) -> 0.15 | I27: {=LLM_C_18!S2:S7} -> 0.1 | J27: =ABS($D27-I27) -> 0.05 | L27: {=LLM_C_19!S2:S7} -> 0 | M27: =ABS($D27-L27) -> 0.05 | P27: {=LLM_C_20!S2:S7} -> 0 | Q27: =ABS($D27-P27) -> 0.05 | S27: {=LLM_C_21!S2:S7} -> 0 | T27: =ABS($D27-S27) -> 0.05 | V27: {=LLM_C_22!S2:S7} -> 0.2 | W27: =ABS($D27-V27) -> 0.15 | Y27: {=LLM_C_23!S2:S7} -> 0.15 | Z27: =ABS($D27-Y27) -> 0.1 | AB27: {=LLM_C_24!S2:S7} -> 0 | AC27: =ABS($D27-AB27) -> 0.05 | AE27: {=LLM_C_25!S2:S7} -> 0 | AF27: =ABS($D27-AE27) -> 0.05 | AH27: {=LLM_C_26!S2:S7} -> 0.2 | AI27: =ABS($D27-AH27) -> 0.15 | AK27: {=LLM_C_27!S2:S7} -> 0.05 | AL27: =ABS($D27-AK27) -> 0 | AN27: {=LLM_C_28!S2:S7} -> 0 | AO27: =ABS($D27-AN27) -> 0.05 | AQ27: {=LLM_C_29!S2:S7} -> 0.1 | AR27: =ABS($D27-AQ27) -> 0.05 | AT27: {=LLM_C_30!S2:S7} -> 0 | AU27: =ABS($D27-AT27) -> 0.05 | AW27: {=LLM_C_31!S2:S7} -> 0.1 | AX27: =ABS($D27-AW27) -> 0.05 | AZ27: {=LLM_C_32!S2:S7} -> 0.2 | BA27: =ABS($D27-AZ27) -> 0.15 | BC27: {=LLM_C_33!S2:S7} -> 0.05 | BD27: =ABS($D27-BC27) -> 0 | BF27: {=LLM_C_34!S2:S7} -> 0.05 | BG27: =ABS($D27-BF27) -> 0 | BK27: Needs Help | BL27: =1-BL8 -> 0.96944444
A28: GPT4 | B28: Confused | C28: Analyzing Object | D28: =COUNTIFS(STUDY03_DATA!C:C,A28,STUDY03_DATA!D:D,B28,STUDY03_DATA!F:F,C28)/'META DATA'!$B$2 -> 0.083333333 | F28: 0 | G28: =ABS($D28-F28) -> 0.083333333 | I28: 0 | J28: =ABS($D28-I28) -> 0.083333333 | L28: 0 | M28: =ABS($D28-L28) -> 0.083333333 | P28: 0 | Q28: =ABS($D28-P28) -> 0.083333333 | S28: 0 | T28: =ABS($D28-S28) -> 0.083333333 | V28: 0 | W28: =ABS($D28-V28) -> 0.083333333 | Y28: 0 | Z28: =ABS($D28-Y28) -> 0.083333333 | AB28: 0 | AC28: =ABS($D28-AB28) -> 0.083333333 | AE28: 0 | AF28: =ABS($D28-AE28) -> 0.083333333 | AH28: 0 | AI28: =ABS($D28-AH28) -> 0.083333333 | AK28: 0.05 | AL28: =ABS($D28-AK28) -> 0.033333333 | AN28: 0 | AO28: =ABS($D28-AN28) -> 0.083333333 | AQ28: 0 | AR28: =ABS($D28-AQ28) -> 0.083333333 | AT28: 0 | AU28: =ABS($D28-AT28) -> 0.083333333 | AW28: 0 | AX28: =ABS($D28-AW28) -> 0.083333333 | AZ28: 0.05 | BA28: =ABS($D28-AZ28) -> 0.033333333 | BC28: 0 | BD28: =ABS($D28-BC28) -> 0.083333333 | BF28: 0 | BG28: =ABS($D28-BF28) -> 0.083333333 | BK28: Confused | BL28: =1-BL9 -> 0.91944444
A29: GPT4 | B29: Confused | C29: Found Object | D29: =COUNTIFS(STUDY03_DATA!C:C,A29,STUDY03_DATA!D:D,B29,STUDY03_DATA!F:F,C29)/'META DATA'!$B$2 -> 0 | F29: 0 | G29: =ABS($D29-F29) -> 0 | I29: 0 | J29: =ABS($D29-I29) -> 0 | L29: 0 | M29: =ABS($D29-L29) -> 0 | P29: 0 | Q29: =ABS($D29-P29) -> 0 | S29: 0 | T29: =ABS($D29-S29) -> 0 | V29: 0 | W29: =ABS($D29-V29) -> 0 | Y29: 0 | Z29: =ABS($D29-Y29) -> 0 | AB29: 0 | AC29: =ABS($D29-AB29) -> 0 | AE29: 0 | AF29: =ABS($D29-AE29) -> 0 | AH29: 0 | AI29: =ABS($D29-AH29) -> 0 | AK29: 0 | AL29: =ABS($D29-AK29) -> 0 | AN29: 0 | AO29: =ABS($D29-AN29) -> 0 | AQ29: 0 | AR29: =ABS($D29-AQ29) -> 0 | AT29: 0 | AU29: =ABS($D29-AT29) -> 0 | AW29: 0 | AX29: =ABS($D29-AW29) -> 0 | AZ29: 0 | BA29: =ABS($D29-AZ29) -> 0 | BC29: 0 | BD29: =ABS($D29-BC29) -> 0 | BF29: 0 | BG29: =ABS($D29-BF29) -> 0 | BJ29: Human | BK29: Waiting for Input | BL29: =1-BL10 -> 0.94444444 | BM29: =AVERAGE(BL29:BL33) -> 0.89111111
A30: GPT4 | B30: Confused | C30: Needs Help | D30: =COUNTIFS(STUDY03_DATA!C:C,A30,STUDY03_DATA!D:D,B30,STUDY03_DATA!F:F,C30)/'META DATA'!$B$2 -> 0.51666667 | F30: 0.45 | G30: =ABS($D30-F30) -> 0.066666667 | I30: 0.35 | J30: =ABS($D30-I30) -> 0.16666667 | L30: 0.6 | M30: =ABS($D30-L30) -> 0.083333333 | P30: 0.4 | Q30: =ABS($D30-P30) -> 0.11666667 | S30: 0.25 | T30: =ABS($D30-S30) -> 0.26666667 | V30: 0.2 | W30: =ABS($D30-V30) -> 0.31666667 | Y30: 0.15 | Z30: =ABS($D30-Y30) -> 0.36666667 | AB30: 0.15 | AC30: =ABS($D30-AB30) -> 0.36666667 | AE30: 0.85 | AF30: =ABS($D30-AE30) -> 0.33333333 | AH30: 0.7 | AI30: =ABS($D30-AH30) -> 0.18333333 | AK30: 0.4 | AL30: =ABS($D30-AK30) -> 0.11666667 | AN30: 0.25 | AO30: =ABS($D30-AN30) -> 0.26666667 | AQ30: 0 | AR30: =ABS($D30-AQ30) -> 0.51666667 | AT30: 0.9 | AU30: =ABS($D30-AT30) -> 0.38333333 | AW30: 0.65 | AX30: =ABS($D30-AW30) -> 0.13333333 | AZ30: 0.35 | BA30: =ABS($D30-AZ30) -> 0.16666667 | BC30: 0.1 | BD30: =ABS($D30-BC30) -> 0.41666667 | BF30: 0.1 | BG30: =ABS($D30-BF30) -> 0.41666667 | BK30: Analyzing Object | BL30: =1-BL11 -> 0.86944444
A31: GPT4 | B31: Confused | C31: Confused | D31: =COUNTIFS(STUDY03_DATA!C:C,A31,STUDY03_DATA!D:D,B31,STUDY03_DATA!F:F,C31)/'META DATA'!$B$2 -> 0.31666667 | F31: 0.15 | G31: =ABS($D31-F31) -> 0.16666667 | I31: 0.3 | J31: =ABS($D31-I31) -> 0.016666667 | L31: 0.25 | M31: =ABS($D31-L31) -> 0.066666667 | P31: 0.6 | Q31: =ABS($D31-P31) -> 0.28333333 | S31: 0.75 | T31: =ABS($D31-S31) -> 0.43333333 | V31: 0.5 | W31: =ABS($D31-V31) -> 0.18333333 | Y31: 0.2 | Z31: =ABS($D31-Y31) -> 0.11666667 | AB31: 0.15 | AC31: =ABS($D31-AB31) -> 0.16666667 | AE31: 0.1 | AF31: =ABS($D31-AE31) -> 0.21666667 | AH31: 0.1 | AI31: =ABS($D31-AH31) -> 0.21666667 | AK31: 0.35 | AL31: =ABS($D31-AK31) -> 0.033333333 | AN31: 0.2 | AO31: =ABS($D31-AN31) -> 0.11666667 | AQ31: 0.1 | AR31: =ABS($D31-AQ31) -> 0.21666667 | AT31: 0.1 | AU31: =ABS($D31-AT31) -> 0.21666667 | AW31: 0.2 | AX31: =ABS($D31-AW31) -> 0.11666667 | AZ31: 0.2 | BA31: =ABS($D31-AZ31) -> 0.11666667 | BC31: 0.5 | BD31: =ABS($D31-BC31) -> 0.18333333 | BF31: 0.15 | BG31: =ABS($D31-BF31) -> 0.16666667 | BK31: Found Object | BL31: =1-BL12 -> 0.93333333
A32: GPT4 | B32: Confused | C32: None | D32: =COUNTIFS(STUDY03_DATA!C:C,A32,STUDY03_DATA!D:D,B32,STUDY03_DATA!F:F,C32)/'META DATA'!$B$2 -> 0.033333333 | F32: 0.2 | G32: =ABS($D32-F32) -> 0.16666667 | I32: 0.2 | J32: =ABS($D32-I32) -> 0.16666667 | L32: 0.1 | M32: =ABS($D32-L32) -> 0.066666667 | P32: 0 | Q32: =ABS($D32-P32) -> 0.033333333 | S32: 0 | T32: =ABS($D32-S32) -> 0.033333333 | V32: 0.1 | W32: =ABS($D32-V32) -> 0.066666667 | Y32: 0.5 | Z32: =ABS($D32-Y32) -> 0.46666667 | AB32: 0.7 | AC32: =ABS($D32-AB32) -> 0.66666667 | AE32: 0 | AF32: =ABS($D32-AE32) -> 0.033333333 | AH32: 0 | AI32: =ABS($D32-AH32) -> 0.033333333 | AK32: 0.15 | AL32: =ABS($D32-AK32) -> 0.11666667 | AN32: 0.55 | AO32: =ABS($D32-AN32) -> 0.51666667 | AQ32: 0.8 | AR32: =ABS($D32-AQ32) -> 0.76666667 | AT32: 0 | AU32: =ABS($D32-AT32) -> 0.033333333 | AW32: 0.05 | AX32: =ABS($D32-AW32) -> 0.016666667 | AZ32: 0.2 | BA32: =ABS($D32-AZ32) -> 0.16666667 | BC32: 0.35 | BD32: =ABS($D32-BC32) -> 0.31666667 | BF32: 0.7 | BG32: =ABS($D32-BF32) -> 0.66666667 | BK32: Needs Help | BL32: =1-BL13 -> 0.78333333
A33: Human | B33: Waiting for Input | C33: Waiting for Input | D33: =COUNTIFS(STUDY03_DATA!C:C,A33,STUDY03_DATA!D:D,B33,STUDY03_DATA!F:F,C33)/'META DATA'!$B$2 -> 0.65 | F33: {=HUM_WFI_14!S2:S7} -> 0.7 | G33: =ABS($D33-F33) -> 0.05 | I33: {=HUM_WFI_18!S2:S7} -> 0.6 | J33: =ABS($D33-I33) -> 0.05 | L33: {=HUM_WFI_19!S2:S7} -> 0.6 | M33: =ABS($D33-L33) -> 0.05 | P33: {=HUM_WFI_20!S2:S7} -> 0.9 | Q33: =ABS($D33-P33) -> 0.25 | S33: {=HUM_WFI_21!S2:S7} -> 0.65 | T33: =ABS($D33-S33) -> 0 | V33: {=HUM_WFI_22!S2:S7} -> 0.6 | W33: =ABS($D33-V33) -> 0.05 | Y33: {=HUM_WFI_23!S2:S7} -> 0.35 | Z33: =ABS($D33-Y33) -> 0.3 | AB33: {=HUM_WFI_24!S2:S7} -> 0.05 | AC33: =ABS($D33-AB33) -> 0.6 | AE33: {=HUM_WFI_25!S2:S7} -> 0.9 | AF33: =ABS($D33-AE33) -> 0.25 | AH33: {=HUM_WFI_26!S2:S7} -> 0.75 | AI33: =ABS($D33-AH33) -> 0.1 | AK33: {=HUM_WFI_27!S2:S7} -> 0.8 | AL33: =ABS($D33-AK33) -> 0.15 | AN33: {=HUM_WFI_28!S2:S7} -> 0.2 | AO33: =ABS($D33-AN33) -> 0.45 | AQ33: {=HUM_WFI_29!S2:S7} -> 0.1 | AR33: =ABS($D33-AQ33) -> 0.55 | AT33: {=HUM_WFI_30!S2:S7} -> 0.85 | AU33: =ABS($D33-AT33) -> 0.2 | AW33: {=HUM_WFI_31!S2:S7} -> 0.65 | AX33: =ABS($D33-AW33) -> 0 | AZ33: {=HUM_WFI_32!S2:S7} -> 0.65 | BA33: =ABS($D33-AZ33) -> 0 | BC33: {=HUM_WFI_33!S2:S7} -> 0.25 | BD33: =ABS($D33-BC33) -> 0.4 | BF33: {=HUM_WFI_34!S2:S7} -> 0.15 | BG33: =ABS($D33-BF33) -> 0.5 | BK33: Confused | BL33: =1-BL14 -> 0.925
A34: Human | B34: Waiting for Input | C34: Analyzing Object | D34: =COUNTIFS(STUDY03_DATA!C:C,A34,STUDY03_DATA!D:D,B34,STUDY03_DATA!F:F,C34)/'META DATA'!$B$2 -> 0.083333333 | F34: 0.15 | G34: =ABS($D34-F34) -> 0.066666667 | I34: 0.15 | J34: =ABS($D34-I34) -> 0.066666667 | L34: 0.15 | M34: =ABS($D34-L34) -> 0.066666667 | P34: 0 | Q34: =ABS($D34-P34) -> 0.083333333 | S34: 0 | T34: =ABS($D34-S34) -> 0.083333333 | V34: 0.1 | W34: =ABS($D34-V34) -> 0.016666667 | Y34: 0.05 | Z34: =ABS($D34-Y34) -> 0.033333333 | AB34: 0.05 | AC34: =ABS($D34-AB34) -> 0.033333333 | AE34: 0.05 | AF34: =ABS($D34-AE34) -> 0.033333333 | AH34: 0.15 | AI34: =ABS($D34-AH34) -> 0.066666667 | AK34: 0.1 | AL34: =ABS($D34-AK34) -> 0.016666667 | AN34: 0.3 | AO34: =ABS($D34-AN34) -> 0.21666667 | AQ34: 0.15 | AR34: =ABS($D34-AQ34) -> 0.066666667 | AT34: 0 | AU34: =ABS($D34-AT34) -> 0.083333333 | AW34: 0.15 | AX34: =ABS($D34-AW34) -> 0.066666667 | AZ34: 0.1 | BA34: =ABS($D34-AZ34) -> 0.016666667 | BC34: 0.05 | BD34: =ABS($D34-BC34) -> 0.033333333 | BF34: 0.1 | BG34: =ABS($D34-BF34) -> 0.016666667 | BJ34: Random | BK34: Waiting for Input | BL34: =1-BL15 -> 0.88611111 | BM34: =AVERAGE(BL34:BL38) -> 0.91666667
A35: Human | B35: Waiting for Input | C35: Found Object | D35: =COUNTIFS(STUDY03_DATA!C:C,A35,STUDY03_DATA!D:D,B35,STUDY03_DATA!F:F,C35)/'META DATA'!$B$2 -> 0.083333333 | F35: 0 | G35: =ABS($D35-F35) -> 0.083333333 | I35: 0 | J35: =ABS($D35-I35) -> 0.083333333 | L35: 0 | M35: =ABS($D35-L35) -> 0.083333333 | P35: 0 | Q35: =ABS($D35-P35) -> 0.083333333 | S35: 0 | T35: =ABS($D35-S35) -> 0.083333333 | V35: 0 | W35: =ABS($D35-V35) -> 0.083333333 | Y35: 0 | Z35: =ABS($D35-Y35) -> 0.083333333 | AB35: 0 | AC35: =ABS($D35-AB35) -> 0.083333333 | AE35: 0 | AF35: =ABS($D35-AE35) -> 0.083333333 | AH35: 0 | AI35: =ABS($D35-AH35) -> 0.083333333 | AK35: 0 | AL35: =ABS($D35-AK35) -> 0.083333333 | AN35: 0 | AO35: =ABS($D35-AN35) -> 0.083333333 | AQ35: 0 | AR35: =ABS($D35-AQ35) -> 0.083333333 | AT35: 0 | AU35: =ABS($D35-AT35) -> 0.083333333 | AW35: 0 | AX35: =ABS($D35-AW35) -> 0.083333333 | AZ35: 0 | BA35: =ABS($D35-AZ35) -> 0.083333333 | BC35: 0 | BD35: =ABS($D35-BC35) -> 0.083333333 | BF35: 0 | BG35: =ABS($D35-BF35) -> 0.083333333 | BK35: Analyzing Object | BL35: =1-BL16 -> 0.96111111
A36: Human | B36: Waiting for Input | C36: Needs Help | D36: =COUNTIFS(STUDY03_DATA!C:C,A36,STUDY03_DATA!D:D,B36,STUDY03_DATA!F:F,C36)/'META DATA'!$B$2 -> 0.05 | F36: 0.05 | G36: =ABS($D36-F36) -> 0 | I36: 0.1 | J36: =ABS($D36-I36) -> 0.05 | L36: 0 | M36: =ABS($D36-L36) -> 0.05 | P36: 0.1 | Q36: =ABS($D36-P36) -> 0.05 | S36: 0.15 | T36: =ABS($D36-S36) -> 0.1 | V36: 0 | W36: =ABS($D36-V36) -> 0.05 | Y36: 0.1 | Z36: =ABS($D36-Y36) -> 0.05 | AB36: 0 | AC36: =ABS($D36-AB36) -> 0.05 | AE36: 0.05 | AF36: =ABS($D36-AE36) -> 0 | AH36: 0.05 | AI36: =ABS($D36-AH36) -> 0 | AK36: 0 | AL36: =ABS($D36-AK36) -> 0.05 | AN36: 0.1 | AO36: =ABS($D36-AN36) -> 0.05 | AQ36: 0.05 | AR36: =ABS($D36-AQ36) -> 0 | AT36: 0.15 | AU36: =ABS($D36-AT36) -> 0.1 | AW36: 0.15 | AX36: =ABS($D36-AW36) -> 0.1 | AZ36: 0.05 | BA36: =ABS($D36-AZ36) -> 0 | BC36: 0 | BD36: =ABS($D36-BC36) -> 0.05 | BF36: 0.05 | BG36: =ABS($D36-BF36) -> 0 | BK36: Found Object | BL36: =1-BL17 -> 0.92777778
A37: Human | B37: Waiting for Input | C37: Confused | D37: =COUNTIFS(STUDY03_DATA!C:C,A37,STUDY03_DATA!D:D,B37,STUDY03_DATA!F:F,C37)/'META DATA'!$B$2 -> 0.066666667 | F37: 0 | G37: =ABS($D37-F37) -> 0.066666667 | I37: 0 | J37: =ABS($D37-I37) -> 0.066666667 | L37: 0 | M37: =ABS($D37-L37) -> 0.066666667 | P37: 0 | Q37: =ABS($D37-P37) -> 0.066666667 | S37: 0.05 | T37: =ABS($D37-S37) -> 0.016666667 | V37: 0.05 | W37: =ABS($D37-V37) -> 0.016666667 | Y37: 0 | Z37: =ABS($D37-Y37) -> 0.066666667 | AB37: 0 | AC37: =ABS($D37-AB37) -> 0.066666667 | AE37: 0 | AF37: =ABS($D37-AE37) -> 0.066666667 | AH37: 0 | AI37: =ABS($D37-AH37) -> 0.066666667 | AK37: 0 | AL37: =ABS($D37-AK37) -> 0.066666667 | AN37: 0 | AO37: =ABS($D37-AN37) -> 0.066666667 | AQ37: 0 | AR37: =ABS($D37-AQ37) -> 0.066666667 | AT37: 0 | AU37: =ABS($D37-AT37) -> 0.066666667 | AW37: 0 | AX37: =ABS($D37-AW37) -> 0.066666667 | AZ37: 0 | BA37: =ABS($D37-AZ37) -> 0.066666667 | BC37: 0 | BD37: =ABS($D37-BC37) -> 0.066666667 | BF37: 0 | BG37: =ABS($D37-BF37) -> 0.066666667 | BK37: Needs Help | BL37: =1-BL18 -> 0.89166667
A38: Human | B38: Waiting for Input | C38: None | D38: =COUNTIFS(STUDY03_DATA!C:C,A38,STUDY03_DATA!D:D,B38,STUDY03_DATA!F:F,C38)/'META DATA'!$B$2 -> 0.066666667 | F38: 0.1 | G38: =ABS($D38-F38) -> 0.033333333 | I38: 0.15 | J38: =ABS($D38-I38) -> 0.083333333 | L38: 0.25 | M38: =ABS($D38-L38) -> 0.18333333 | P38: 0 | Q38: =ABS($D38-P38) -> 0.066666667 | S38: 0.15 | T38: =ABS($D38-S38) -> 0.083333333 | V38: 0.25 | W38: =ABS($D38-V38) -> 0.18333333 | Y38: 0.5 | Z38: =ABS($D38-Y38) -> 0.43333333 | AB38: 0.9 | AC38: =ABS($D38-AB38) -> 0.83333333 | AE38: 0 | AF38: =ABS($D38-AE38) -> 0.066666667 | AH38: 0 | AI38: =ABS($D38-AH38) -> 0.066666667 | AK38: 0.05 | AL38: =ABS($D38-AK38) -> 0.016666667 | AN38: 0.4 | AO38: =ABS($D38-AN38) -> 0.33333333 | AQ38: 0.7 | AR38: =ABS($D38-AQ38) -> 0.63333333 | AT38: 0 | AU38: =ABS($D38-AT38) -> 0.066666667 | AW38: 0 | AX38: =ABS($D38-AW38) -> 0.066666667 | AZ38: 0.2 | BA38: =ABS($D38-AZ38) -> 0.13333333 | BC38: 0.7 | BD38: =ABS($D38-BC38) -> 0.63333333 | BF38: 0.7 | BG38: =ABS($D38-BF38) -> 0.63333333 | BK38: Confused | BL38: =1-BL19 -> 0.91666667
A39: Human | B39: Analyzing Object | C39: Waiting for Input | D39: =COUNTIFS(STUDY03_DATA!C:C,A39,STUDY03_DATA!D:D,B39,STUDY03_DATA!F:F,C39)/'META DATA'!$B$2 -> 0 | F39: {=HUM_AO_14!S2:S7} -> 0.05 | G39: =ABS($D39-F39) -> 0.05 | I39: {=HUM_AO_18!S2:S7} -> 0 | J39: =ABS($D39-I39) -> 0 | L39: {=HUM_AO_19!S2:S7} -> 0.05 | M39: =ABS($D39-L39) -> 0.05 | P39: {=HUM_AO_20!S2:S7} -> 0 | Q39: =ABS($D39-P39) -> 0 | S39: {=HUM_AO_21!S2:S7} -> 0 | T39: =ABS($D39-S39) -> 0 | V39: {=HUM_AO_22!S2:S7} -> 0 | W39: =ABS($D39-V39) -> 0 | Y39: {=HUM_AO_23!S2:S7} -> 0.1 | Z39: =ABS($D39-Y39) -> 0.1 | AB39: {=HUM_AO_24!S2:S7} -> 0 | AC39: =ABS($D39-AB39) -> 0 | AE39: {=HUM_AO_25!S2:S7} -> 0 | AF39: =ABS($D39-AE39) -> 0 | AH39: {=HUM_AO_26!S2:S7} -> 0 | AI39: =ABS($D39-AH39) -> 0 | AK39: {=HUM_AO_27!S2:S7} -> 0.05 | AL39: =ABS($D39-AK39) -> 0.05 | AN39: {=HUM_AO_28!S2:S7} -> 0 | AO39: =ABS($D39-AN39) -> 0 | AQ39: {=HUM_AO_29!S2:S7} -> 0 | AR39: =ABS($D39-AQ39) -> 0 | AT39: {=HUM_AO_30!S2:S7} -> 0 | AU39: =ABS($D39-AT39) -> 0 | AW39: {=HUM_AO_31!S2:S7} -> 0 | AX39: =ABS($D39-AW39) -> 0 | AZ39: {=HUM_AO_32!S2:S7} -> 0 | BA39: =ABS($D39-AZ39) -> 0 | BC39: {=HUM_AO_33!S2:S7} -> 0.05 | BD39: =ABS($D39-BC39) -> 0.05 | BF39: {=HUM_AO_34!S2:S7} -> 0 | BG39: =ABS($D39-BF39) -> 0
A40: Human | B40: Analyzing Object | C40: Analyzing Object | D40: =COUNTIFS(STUDY03_DATA!C:C,A40,STUDY03_DATA!D:D,B40,STUDY03_DATA!F:F,C40)/'META DATA'!$B$2 -> 0.55 | F40: 0.65 | G40: =ABS($D40-F40) -> 0.1 | I40: 0.7 | J40: =ABS($D40-I40) -> 0.15 | L40: 0.7 | M40: =ABS($D40-L40) -> 0.15 | P40: 0.95 | Q40: =ABS($D40-P40) -> 0.4 | S40: 0.9 | T40: =ABS($D40-S40) -> 0.35 | V40: 0.7 | W40: =ABS($D40-V40) -> 0.15 | Y40: 0.4 | Z40: =ABS($D40-Y40) -> 0.15 | AB40: 0.15 | AC40: =ABS($D40-AB40) -> 0.4 | AE40: 0.95 | AF40: =ABS($D40-AE40) -> 0.4 | AH40: 0.8 | AI40: =ABS($D40-AH40) -> 0.25 | AK40: 0.65 | AL40: =ABS($D40-AK40) -> 0.1 | AN40: 0.5 | AO40: =ABS($D40-AN40) -> 0.05 | AQ40: 0.1 | AR40: =ABS($D40-AQ40) -> 0.45 | AT40: 1 | AU40: =ABS($D40-AT40) -> 0.45 | AW40: 0.85 | AX40: =ABS($D40-AW40) -> 0.3 | AZ40: 0.85 | BA40: =ABS($D40-AZ40) -> 0.3 | BC40: 0.4 | BD40: =ABS($D40-BC40) -> 0.15 | BF40: 0.15 | BG40: =ABS($D40-BF40) -> 0.4 | BJ40: USER STUDY 03 Classification Accuracy Data
...

Sheet PROXY_RESULTS_ATTEMPTS
A1: CONDITION | B1: REAL STATE | C1: STATE SELECTION OPTIONS | D1: SURVEY 03 | F1: ATTEMPT 01 | I1: ATTEMPT 02 | L1: ATTEMPT 03 | O1: ATTEMPT 04 | R1: ATTEMPT 05 | U1: ATTEMPT 06 | X1: ATTEMPT 07 | AA1: ATTEMPT 08 | AF1: ATTEMPT 10 | AI1: ATTEMPT 11 | AL1: ATTEMPT 12 | AO1: ATTEMPT 13 | AR1: ATTEMPT 14 | AU1: ATTEMPT 15 | AX1: ATTEMPT 16 | BA1: ATTEMPT 17 | BD1: ATTEMPT 18 | BG1: ATTEMPT 19
D2: HUMAN RESPONSE (%) | F2: PROXY RESPONSE (%) | G2: ABS DELTA | I2: PROXY RESPONSE (%) | J2: ABS DELTA | L2: PROXY RESPONSE (%) | M2: ABS DELTA | O2: PROXY RESPONSE (%) | P2: ABS DELTA | R2: PROXY RESPONSE (%) | S2: ABS DELTA | U2: PROXY RESPONSE (%) | V2: ABS DELTA | X2: PROXY RESPONSE (%) | Y2: ABS DELTA | AA2: PROXY RESPONSE (%) | AB2: ABS DELTA | AF2: PROXY RESPONSE (%) | AG2: ABS DELTA | AI2: PROXY RESPONSE (%) | AJ2: ABS DELTA | AL2: PROXY RESPONSE (%) | AM2: ABS DELTA | AO2: PROXY RESPONSE (%) | AP2: ABS DELTA | AR2: PROXY RESPONSE (%) | AS2: ABS DELTA | AU2: PROXY RESPONSE (%) | AV2: ABS DELTA | AX2: PROXY RESPONSE (%) | AY2: ABS DELTA | BA2: PROXY RESPONSE (%) | BB2: ABS DELTA | BD2: PROXY RESPONSE (%) | BE2: ABS DELTA | BG2: PROXY RESPONSE (%) | BH2: ABS DELTA
A3: GPT4 | B3: Waiting for Input | C3: Waiting for Input | D3: =COUNTIFS(STUDY03_DATA!C:C,A3,STUDY03_DATA!D:D,B3,STUDY03_DATA!F:F,C3)/'META DATA'!$B$2 -> 0.73333333 | F3: {=LLM_WFI_01!S2:S7} -> 0.7 | G3: =ABS($D3-F3) -> 0.033333333 | I3: {=LLM_WFI_02!S2:S7} -> 0.75 | J3: =ABS($D3-I3) -> 0.016666667 | L3: {=LLM_WFI_03!S2:S7} -> 0.6 | M3: =ABS($D3-L3) -> 0.13333333 | O3: {=LLM_WFI_04!S2:S7} -> 0.75 | P3: =ABS($D3-O3) -> 0.016666667 | R3: {=LLM_WFI_05!S2:S7} -> 0.35 | S3: =ABS($D3-R3) -> 0.38333333 | U3: {=LLM_WFI_06!S2:S7} -> 0.75 | V3: =ABS($D3-U3) -> 0.016666667 | X3: {=LLM_WFI_07!S2:S7} -> 0.8 | Y3: =ABS($D3-X3) -> 0.066666667 | AA3: {=LLM_WFI_08!S2:S7} -> 0.5 | AB3: =ABS($D3-AA3) -> 0.23333333 | AF3: {=LLM_WFI_10!S2:S7} -> 0.65 | AG3: =ABS($D3-AF3) -> 0.083333333 | AI3: {=LLM_WFI_11!S2:S7} -> 0.6 | AJ3: =ABS($D3-AI3) -> 0.13333333 | AL3: {=LLM_WFI_12!S2:S7} -> 0.65 | AM3: =ABS($D3-AL3) -> 0.083333333 | AO3: {=LLM_WFI_13!S2:S7} -> 0.75 | AP3: =ABS($D3-AO3) -> 0.016666667 | AR3: {=LLM_WFI_14!S2:S7} -> 0.7 | AS3: =ABS($D3-AR3) -> 0.033333333 | AU3: {=LLM_WFI_15!S2:S7} -> 0.85 | AV3: =ABS($D3-AU3) -> 0.11666667 | AX3: {=LLM_WFI_16!S2:S7} -> 0.4 | AY3: =ABS($D3-AX3) -> 0.33333333 | BA3: {=LLM_WFI_17!S2:S7} -> 0.55 | BB3: =ABS($D3-BA3) -> 0.18333333 | BD3: {=LLM_WFI_18!S2:S7} -> 0.7 | BE3: =ABS($D3-BD3) -> 0.033333333 | BG3: {=LLM_WFI_19!S2:S7} -> 0.75 | BH3: =ABS($D3-BG3) -> 0.016666667 | BR3: GPT GENERATED WAITING FOR INPUT
A4: GPT4 | B4: Waiting for Input | C4: Analyzing Object | D4: =COUNTIFS(STUDY03_DATA!C:C,A4,STUDY03_DATA!D:D,B4,STUDY03_DATA!F:F,C4)/'META DATA'!$B$2 -> 0.016666667 | F4: 0.05 | G4: =ABS($D4-F4) -> 0.033333333 | I4: 0.05 | J4: =ABS($D4-I4) -> 0.033333333 | L4: 0.05 | M4: =ABS($D4-L4) -> 0.033333333 | O4: 0.1 | P4: =ABS($D4-O4) -> 0.083333333 | R4: 0.4 | S4: =ABS($D4-R4) -> 0.38333333 | U4: 0.1 | V4: =ABS($D4-U4) -> 0.083333333 | X4: 0.1 | Y4: =ABS($D4-X4) -> 0.083333333 | AA4: 0.35 | AB4: =ABS($D4-AA4) -> 0.33333333 | AF4: 0.05 | AG4: =ABS($D4-AF4) -> 0.033333333 | AI4: 0 | AJ4: =ABS($D4-AI4) -> 0.016666667 | AL4: 0.25 | AM4: =ABS($D4-AL4) -> 0.23333333 | AO4: 0.15 | AP4: =ABS($D4-AO4) -> 0.13333333 | AR4: 0.05 | AS4: =ABS($D4-AR4) -> 0.033333333 | AU4: 0.15 | AV4: =ABS($D4-AU4) -> 0.13333333 | AX4: 0.35 | AY4: =ABS($D4-AX4) -> 0.33333333 | BA4: 0.35 | BB4: =ABS($D4-BA4) -> 0.33333333 | BD4: 0.05 | BE4: =ABS($D4-BD4) -> 0.033333333 | BG4: 0.05 | BH4: =ABS($D4-BG4) -> 0.033333333 | BL4: ACCURACY PROXY VALIDATION DATA (MEAN ABS ERROR = MAE) | ID 06
A5: GPT4 | B5: Waiting for Input | C5: Found Object | D5: =COUNTIFS(STUDY03_DATA!C:C,A5,STUDY03_DATA!D:D,B5,STUDY03_DATA!F:F,C5)/'META DATA'!$B$2 -> 0.016666667 | F5: 0 | G5: =ABS($D5-F5) -> 0.016666667 | I5: 0 | J5: =ABS($D5-I5) -> 0.016666667 | L5: 0 | M5: =ABS($D5-L5) -> 0.016666667 | O5: 0 | P5: =ABS($D5-O5) -> 0.016666667 | R5: 0.2 | S5: =ABS($D5-R5) -> 0.18333333 | U5: 0.05 | V5: =ABS($D5-U5) -> 0.033333333 | X5: 0 | Y5: =ABS($D5-X5) -> 0.016666667 | AA5: 0.05 | AB5: =ABS($D5-AA5) -> 0.033333333 | AF5: 0 | AG5: =ABS($D5-AF5) -> 0.016666667 | AI5: 0 | AJ5: =ABS($D5-AI5) -> 0.016666667 | AL5: 0 | AM5: =ABS($D5-AL5) -> 0.016666667 | AO5: 0 | AP5: =ABS($D5-AO5) -> 0.016666667 | AR5: 0 | AS5: =ABS($D5-AR5) -> 0.016666667 | AU5: 0 | AV5: =ABS($D5-AU5) -> 0.016666667 | AX5: 0.1 | AY5: =ABS($D5-AX5) -> 0.083333333 | BA5: 0.05 | BB5: =ABS($D5-BA5) -> 0.033333333 | BD5: 0 | BE5: =ABS($D5-BD5) -> 0.016666667 | BG5: 0 | BH5: =ABS($D5-BG5) -> 0.016666667 | BL5: Condition | BM5: State | BN5: Delta by State | BO5: Delta by Cond | BP5: Overall Delta
A6: GPT4 | B6: Waiting for Input | C6: Needs Help | D6: =COUNTIFS(STUDY03_DATA!C:C,A6,STUDY03_DATA!D:D,B6,STUDY03_DATA!F:F,C6)/'META DATA'!$B$2 -> 0.05 | F6: 0.1 | G6: =ABS($D6-F6) -> 0.05 | I6: 0 | J6: =ABS($D6-I6) -> 0.05 | L6: 0.05 | M6: =ABS($D6-L6) -> 0 | O6: 0.05 | P6: =ABS($D6-O6) -> 0 | R6: 0 | S6: =ABS($D6-R6) -> 0.05 | U6: 0.05 | V6: =ABS($D6-U6) -> 0 | X6: 0 | Y6: =ABS($D6-X6) -> 0.05 | AA6: 0 | AB6: =ABS($D6-AA6) -> 0.05 | AF6: 0.1 | AG6: =ABS($D6-AF6) -> 0.05 | AI6: 0 | AJ6: =ABS($D6-AI6) -> 0.05 | AL6: 0 | AM6: =ABS($D6-AL6) -> 0.05 | AO6: 0 | AP6: =ABS($D6-AO6) -> 0.05 | AR6: 0 | AS6: =ABS($D6-AR6) -> 0.05 | AU6: 0 | AV6: =ABS($D6-AU6) -> 0.05 | AX6: 0 | AY6: =ABS($D6-AX6) -> 0.05 | BA6: 0.05 | BB6: =ABS($D6-BA6) -> 0 | BD6: 0 | BE6: =ABS($D6-BD6) -> 0.05 | BG6: 0 | BH6: =ABS($D6-BG6) -> 0.05 | BL6: GPT4 | BM6: Waiting for Input | BN6: =AVERAGE(V3:V8) -> 0.044444444 | BO6: =AVERAGE(BN6:BN10) -> 0.10611111 | BP6: =AVERAGE(BO6,BO11,BO16) -> 0.11777778
A7: GPT4 | B7: Waiting for Input | C7: Confused | D7: =COUNTIFS(STUDY03_DATA!C:C,A7,STUDY03_DATA!D:D,B7,STUDY03_DATA!F:F,C7)/'META DATA'!$B$2 -> 0.066666667 | F7: 0.1 | G7: =ABS($D7-F7) -> 0.033333333 | I7: 0.1 | J7: =ABS($D7-I7) -> 0.033333333 | L7: 0.2 | M7: =ABS($D7-L7) -> 0.13333333 | O7: 0.1 | P7: =ABS($D7-O7) -> 0.033333333 | R7: 0 | S7: =ABS($D7-R7) -> 0.066666667 | U7: 0 | V7: =ABS($D7-U7) -> 0.066666667 | X7: 0.05 | Y7: =ABS($D7-X7) -> 0.016666667 | AA7: 0.05 | AB7: =ABS($D7-AA7) -> 0.016666667 | AF7: 0.05 | AG7: =ABS($D7-AF7) -> 0.016666667 | AI7: 0 | AJ7: =ABS($D7-AI7) -> 0.066666667 | AL7: 0 | AM7: =ABS($D7-AL7) -> 0.066666667 | AO7: 0 | AP7: =ABS($D7-AO7) -> 0.066666667 | AR7: 0 | AS7: =ABS($D7-AR7) -> 0.066666667 | AU7: 0 | AV7: =ABS($D7-AU7) -> 0.066666667 | AX7: 0 | AY7: =ABS($D7-AX7) -> 0.066666667 | BA7: 0 | BB7: =ABS($D7-BA7) -> 0.066666667 | BD7: 0 | BE7: =ABS($D7-BD7) -> 0.066666667 | BG7: 0 | BH7: =ABS($D7-BG7) -> 0.066666667 | BM7: Analyzing Object | BN7: =AVERAGE(V9:V14) -> 0.1
A8: GPT4 | B8: Waiting for Input | C8: None | D8: =COUNTIFS(STUDY03_DATA!C:C,A8,STUDY03_DATA!D:D,B8,STUDY03_DATA!F:F,C8)/'META DATA'!$B$2 -> 0.11666667 | F8: 0.05 | G8: =ABS($D8-F8) -> 0.066666667 | I8: 0.1 | J8: =ABS($D8-I8) -> 0.016666667 | L8: 0.1 | M8: =ABS($D8-L8) -> 0.016666667 | O8: 0 | P8: =ABS($D8-O8) -> 0.11666667 | R8: 0.05 | S8: =ABS($D8-R8) -> 0.066666667 | U8: 0.05 | V8: =ABS($D8-U8) -> 0.066666667 | X8: 0.05 | Y8: =ABS($D8-X8) -> 0.066666667 | AA8: 0.05 | AB8: =ABS($D8-AA8) -> 0.066666667 | AF8: 0.15 | AG8: =ABS($D8-AF8) -> 0.033333333 | AI8: 0.35 | AJ8: =ABS($D8-AI8) -> 0.23333333 | AL8: 0.1 | AM8: =ABS($D8-AL8) -> 0.016666667 | AO8: 0.1 | AP8: =ABS($D8-AO8) -> 0.016666667 | AR8: 0.25 | AS8: =ABS($D8-AR8) -> 0.13333333 | AU8: 0 | AV8: =ABS($D8-AU8) -> 0.11666667 | AX8: 0.1 | AY8: =ABS($D8-AX8) -> 0.016666667 | BA8: 0 | BB8: =ABS($D8-BA8) -> 0.11666667 | BD8: 0.25 | BE8: =ABS($D8-BD8) -> 0.13333333 | BG8: 0.2 | BH8: =ABS($D8-BG8) -> 0.083333333 | BM8: Found Object | BN8: =AVERAGE(V15:V20) -> 0.12222222
A9: GPT4 | B9: Analyzing Object | C9: Waiting for Input | D9: =COUNTIFS(STUDY03_DATA!C:C,A9,STUDY03_DATA!D:D,B9,STUDY03_DATA!F:F,C9)/'META DATA'!$B$2 -> 0.083333333 | F9: {=LLM_AO_01!S2:S7} -> 0.15 | G9: =ABS($D9-F9) -> 0.066666667 | I9: {=LLM_AO_02!S2:S7} -> 0.15 | J9: =ABS($D9-I9) -> 0.066666667 | L9: {=LLM_AO_03!S2:S7} -> 0.35 | M9: =ABS($D9-L9) -> 0.26666667 | O9: {=LLM_AO_04!S2:S7} -> 0.05 | P9: =ABS($D9-O9) -> 0.033333333 | R9: {=LLM_AO_05!S2:S7} -> 0.2 | S9: =ABS($D9-R9) -> 0.11666667 | U9: {=LLM_AO_06!S2:S7} -> 0.1 | V9: =ABS($D9-U9) -> 0.016666667 | X9: {=LLM_AO_07!S2:S7} -> 0 | Y9: =ABS($D9-X9) -> 0.083333333 | AA9: {=LLM_AO_08!S2:S7} -> 0.15 | AB9: =ABS($D9-AA9) -> 0.066666667 | AF9: {=LLM_AO_10!S2:S7} -> 0.3 | AG9: =ABS($D9-AF9) -> 0.21666667 | AI9: {=LLM_AO_11!S2:S7} -> 0.15 | AJ9: =ABS($D9-AI9) -> 0.066666667 | AL9: {=LLM_AO_12!S2:S7} -> 0 | AM9: =ABS($D9-AL9) -> 0.083333333 | AO9: {=LLM_AO_13!S2:S7} -> 0.15 | AP9: =ABS($D9-AO9) -> 0.066666667 | AR9: {=LLM_AO_14!S2:S7} -> 0.2 | AS9: =ABS($D9-AR9) -> 0.11666667 | AU9: {=LLM_AO_15!S2:S7} -> 0.15 | AV9: =ABS($D9-AU9) -> 0.066666667 | AX9: {=LLM_AO_16!S2:S7} -> 0.2 | AY9: =ABS($D9-AX9) -> 0.11666667 | BA9: {=LLM_AO_17!S2:S7} -> 0.25 | BB9: =ABS($D9-BA9) -> 0.16666667 | BD9: {=LLM_AO_18!S2:S7} -> 0.2 | BE9: =ABS($D9-BD9) -> 0.11666667 | BG9: {=LLM_AO_19!S2:S7} -> 0.35 | BH9: =ABS($D9-BG9) -> 0.26666667 | BM9: Needs Help | BN9: =AVERAGE(V21:V26) -> 0.077777778
A10: GPT4 | B10: Analyzing Object | C10: Analyzing Object | D10: =COUNTIFS(STUDY03_DATA!C:C,A10,STUDY03_DATA!D:D,B10,STUDY03_DATA!F:F,C10)/'META DATA'!$B$2 -> 0.33333333 | F10: 0.7 | G10: =ABS($D10-F10) -> 0.36666667 | I10: 0.8 | J10: =ABS($D10-I10) -> 0.46666667 | L10: 0.3 | M10: =ABS($D10-L10) -> 0.033333333 | O10: 0.8 | P10: =ABS($D10-O10) -> 0.46666667 | R10: 0.5 | S10: =ABS($D10-R10) -> 0.16666667 | U10: 0.45 | V10: =ABS($D10-U10) -> 0.11666667 | X10: 0.65 | Y10: =ABS($D10-X10) -> 0.31666667 | AA10: 0.55 | AB10: =ABS($D10-AA10) -> 0.21666667 | AF10: 0.35 | AG10: =ABS($D10-AF10) -> 0.016666667 | AI10: 0.6 | AJ10: =ABS($D10-AI10) -> 0.26666667 | AL10: 0.8 | AM10: =ABS($D10-AL10) -> 0.46666667 | AO10: 0.75 | AP10: =ABS($D10-AO10) -> 0.41666667 | AR10: 0.45 | AS10: =ABS($D10-AR10) -> 0.11666667 | AU10: 0.7 | AV10: =ABS($D10-AU10) -> 0.36666667 | AX10: 0.6 | AY10: =ABS($D10-AX10) -> 0.26666667 | BA10: 0.65 | BB10: =ABS($D10-BA10) -> 0.31666667 | BD10: 0.4 | BE10: =ABS($D10-BD10) -> 0.066666667 | BG10: 0.35 | BH10: =ABS($D10-BG10) -> 0.016666667 | BM10: Confused | BN10: =AVERAGE(V27:V32) -> 0.18611111
