Workbook

Sheet RAW_w_CALCS
A1: StartDate | B1: EndDate | C1: Status | D1: IPAddress | E1: Progress | F1: Duration (in seconds) | G1: Finished | H1: RecordedDate | I1: ResponseId | J1: RecipientLastName | K1: RecipientFirstName | L1: RecipientEmail | M1: ExternalReference | N1: LocationLatitude | O1: LocationLongitude | P1: DistributionChannel | Q1: UserLanguage | R1: Q_RecaptchaScore | S1: 00-01_1 | T1: 00-01_2 | U1: 00-01_3 | V1: 00-01_4 | W1: 02-01 | X1: 02-02 | Y1: 02-03_1 | Z1: 02-03_2 | AA1: 02-03_3 | AB1: 02-03_4 | AC1: SPR_ISO_WFI_MOT_VID | AD1: SPR_ISO_WFI_MOT_CON | AE1: SPR_ISO_WFI_MOT_TIM_First Click | AF1: SPR_ISO_WFI_MOT_TIM_Last Click | AG1: SPR_ISO_WFI_MOT_TIM_Page Submit | AH1: SPR_ISO_WFI_MOT_TIM_Click Count | AI1: SPR_ISO_AO_MOT_VID | AJ1: SPR_ISO_AO_MOT_CON | AK1: SPR_ISO_AO_MOT_TIM_First Click | AL1: SPR_ISO_AO_MOT_TIM_Last Click | AM1: SPR_ISO_AO_MOT_TIM_Page Submit | AN1: SPR_ISO_AO_MOT_TIM_Click Count | AO1: SPR_ISO_FO_MOT_VID | AP1: SPR_ISO_FO_MOT_CON | AQ1: SPR_ISO_FO_MOT_TIM_First Click | AR1: SPR_ISO_FO_MOT_TIM_Last Click | AS1: SPR_ISO_FO_MOT_TIM_Page Submit | AT1: SPR_ISO_FO_MOT_TIM_Click Count | AU1: SPR_ISO_ER_MOT_VID | AV1: SPR_ISO_ER_MOT_CON | AW1: SPR_ISO_ER_MOT_TIM_First Click | AX1: SPR_ISO_ER_MOT_TIM_Last Click | AY1: SPR_ISO_ER_MOT_TIM_Page Submit | AZ1: SPR_ISO_ER_MOT_TIM_Click Count | BA1: SPR_ISO_CO_MOT_VID | BB1: SPR_ISO_CO_MOT_CON | BC1: SPR_ISO_CO_MOT_TIM_First Click | BD1: SPR_ISO_CO_MOT_TIM_Last Click | BE1: SPR_ISO_CO_MOT_TIM_Page Submit | BF1: SPR_ISO_CO_MOT_TIM_Click Count | BG1: SPR_NON_WFI_MOT_VID | BH1: SPR_NON_WFI_MOT_CON | BI1: SPR_NON_WFI_MOT_TIM_First Click | BJ1: SPR_NON_WFI_MOT_TIM_Last Click | BK1: SPR_NON_WFI_MOT_TIM_Page Submit | BL1: SPR_NON_WFI_MOT_TIM_Click Count | BM1: SPR_NON_AO_MOT_VID | BN1: SPR_NON_AO_MOT_CON | BO1: SPR_NON_AO_MOT_TIM_First Click | BP1: SPR_NON_AO_MOT_TIM_Last Click | BQ1: SPR_NON_AO_MOT_TIM_Page Submit | BR1: SPR_NON_AO_MOT_TIM_Click Count | BS1: SPR_NON_FO_MOT_VID | BT1: SPR_NON_FO_MOT_CON | BU1: SPR_NON_FO_MOT_TIM_First Click | BV1: SPR_NON_FO_MOT_TIM_Last Click | BW1: SPR_NON_FO_MOT_TIM_Page Submit | BX1: SPR_NON_FO_MOT_TIM_Click Count | BY1: SPR_NON_ER_MOT_VID | BZ1: SPR_NON_ER_MOT_CON | CA1: SPR_NON_ER_MOT_TIM_First Click | CB1: SPR_NON_ER_MOT_TIM_Last Click | CC1: SPR_NON_ER_MOT_TIM_Page Submit | CD1: SPR_NON_ER_MOT_TIM_Click Count | CE1: SPR_NON_CO_MOT_VID | CF1: SPR_NON_CO_MOT_CON | CG1: SPR_NON_CO_MOT_TIM_First Click | CH1: SPR_NON_CO_MOT_TIM_Last Click | CI1: SPR_NON_CO_MOT_TIM_Page Submit | CJ1: SPR_NON_CO_MOT_TIM_Click Count | CK1: SPR_EMD_WFI_MOT_VID | CL1: SPR_EMD_WFI_MOT_CON | CM1: SPR_EMD_WFI_MOT_TIM_First Click | CN1: SPR_EMD_WFI_MOT_TIM_Last Click | CO1: SPR_EMD_WFI_MOT_TIM_Page Submit | CP1: SPR_EMD_WFI_MOT_TIM_Click Count | CQ1: SPR_EMD_AO_MOT_VID | CR1: SPR_EMD_AO_MOT_CON | CS1: SPR_EMD_AO_MOT_TIM_First Click | CT1: SPR_EMD_AO_MOT_TIM_Last Click | CU1: SPR_EMD_AO_MOT_TIM_Page Submit | CV1: SPR_EMD_AO_MOT_TIM_Click Count | CW1: SPR_EMD_FO_MOT_VID | CX1: SPR_EMD_FO_MOT_CON | CY1: SPR_EMD_FO_MOT_TIM_First Click | CZ1: SPR_EMD_FO_MOT_TIM_Last Click | DA1: SPR_EMD_FO_MOT_TIM_Page Submit | DB1: SPR_EMD_FO_MOT_TIM_Click Count | DC1: SPR_EMD_ER_MOT_VID | DD1: SPR_EMD_ER_MOT_CON | DE1: SPR_EMD_ER_MOT_TIM_First Click | DF1: SPR_EMD_ER_MOT_TIM_Last Click | DG1: SPR_EMD_ER_MOT_TIM_Page Submit | DH1: SPR_EMD_ER_MOT_TIM_Click Count | DI1: SPR_EMD_CO_MOT_VID | DJ1: SPR_EMD_CO_MOT_CON | DK1: SPR_EMD_CO_MOT_TIM_First Click | DL1: SPR_EMD_CO_MOT_TIM_Last Click | DM1: SPR_EMD_CO_MOT_TIM_Page Submit | DN1: SPR_EMD_CO_MOT_TIM_Click Count | DO1: SPR_DYN_WFI_MOT_VID | DP1: SPR_DYN_WFI_MOT_CON | DQ1: SPR_DYN_WFI_MOT_TIM_First Click | DR1: SPR_DYN_WFI_MOT_TIM_Last Click | DS1: SPR_DYN_WFI_MOT_TIM_Page Submit | DT1: SPR_DYN_WFI_MOT_TIM_Click Count | DU1: SPR_DYN_AO_MOT_VID | DV1: SPR_DYN_AO_MOT_CON | DW1: SPR_DYN_AO_MOT_TIM_First Click | DX1: SPR_DYN_AO_MOT_TIM_Last Click | DY1: SPR_DYN_AO_MOT_TIM_Page Submit | DZ1: SPR_DYN_AO_MOT_TIM_Click Count | EA1: SPR_DYN_FO_MOT_VID | EB1: SPR_DYN_FO_MOT_CON | EC1: SPR_DYN_FO_MOT_TIM_First Click | ED1: SPR_DYN_FO_MOT_TIM_Last Click | EE1: SPR_DYN_FO_MOT_TIM_Page Submit | EF1: SPR_DYN_FO_MOT_TIM_Click Count | EG1: SPR_DYN_ER_MOT_VID | EH1: SPR_DYN_ER_MOT_CON | EI1: SPR_DYN_ER_MOT_TIM_First Click | EJ1: SPR_DYN_ER_MOT_TIM_Last Click | EK1: SPR_DYN_ER_MOT_TIM_Page Submit | EL1: SPR_DYN_ER_MOT_TIM_Click Count | EM1: SPR_DYN_CO_MOT_VID | EN1: SPR_DYN_CO_MOT_CON | EO1: SPR_DYN_CO_MOT_TIM_First Click | EP1: SPR_DYN_CO_MOT_TIM_Last Click | EQ1: SPR_DYN_CO_MOT_TIM_Page Submit | ER1: SPR_DYN_CO_MOT_TIM_Click Count | ES1: MIN_ISO_WFI_MOT_VID | ET1: MIN_ISO_WFI_MOT_CON | EU1: MIN_ISO_WFI_MOT_TIM_First Click | EV1: MIN_ISO_WFI_MOT_TIM_Last Click | EW1: MIN_ISO_WFI_MOT_TIM_Page Submit | EX1: MIN_ISO_WFI_MOT_TIM_Click Count | EY1: MIN_ISO_IWO_VID | EZ1: MIN_ISO_IWO_CON | FA1: MIN_ISO_IWO_TIM_First Click | FB1: MIN_ISO_IWO_TIM_Last Click | FC1: MIN_ISO_IWO_TIM_Page Submit | FD1: MIN_ISO_IWO_TIM_Click Count | FE1: MIN_ISO_NH_MOT_VID | FF1: MIN_ISO_NH_MOT_CON | FG1: Q748_First Click | FH1: Q748_Last Click | FI1: Q748_Page Submit | FJ1: Q748_Click Count | FK1: MIN_NON_WFI_MOT_VID | FL1: MIN_NON_WFI_MOT_CON | FM1: MIN_NON_WFI_MOT_TIM_First Click | FN1: MIN_NON_WFI_MOT_TIM_Last Click | FO1: MIN_NON_WFI_MOT_TIM_Page Submit | FP1: MIN_NON_WFI_MOT_TIM_Click Count | FQ1: MIN_NON_IWO_VID | FR1: MIN_NON_IWO_CON | FS1: MIN_NON_IWO_TIM_First Click | FT1: MIN_NON_IWO_TIM_Last Click | FU1: MIN_NON_IWO_TIM_Page Submit | FV1: MIN_NON_IWO_TIM_Click Count | FW1: MIN_NON_NH_MOT_VID | FX1: MIN_NON_NH_MOT_CON | FY1: MIN_NON_NH_MOT_TIM_First Click | FZ1: MIN_NON_NH_MOT_TIM_Last Click | GA1: MIN_NON_NH_MOT_TIM_Page Submit | GB1: MIN_NON_NH_MOT_TIM_Click Count | GC1: MIN_EMD_WFI_MOT_VID | GD1: MIN_EMD_WFI_MOT_CON | GE1: MIN_EMD_WFI_MOT_TIM_First Click | GF1: MIN_EMD_WFI_MOT_TIM_Last Click | GG1: MIN_EMD_WFI_MOT_TIM_Page Submit | GH1: MIN_EMD_WFI_MOT_TIM_Click Count | GI1: MIN_EMD_IWO_MOT_VID | GJ1: MIN_EMD_IWO_MOT_CON | GK1: MIN_EMD_IWO_MOT_TIM_First Click | GL1: MIN_EMD_IWO_MOT_TIM_Last Click | GM1: MIN_EMD_IWO_MOT_TIM_Page Submit | GN1: MIN_EMD_IWO_MOT_TIM_Click Count | GO1: MIN_EMD_NH_MOT_VID | GP1: MIN_EMD_NH_MOT_CON | GQ1: MIN_EMD_NH_MOT_TIM_First Click | GR1: MIN_EMD_NH_MOT_TIM_Last Click | GS1: MIN_EMD_NH_MOT_TIM_Page Submit | GT1: MIN_EMD_NH_MOT_TIM_Click Count | GU1: MIN_DYN_WFI_MOT_VID | GV1: MIN_DYN_WFI_MOT_CON | GW1: MIN_DYN_WFI_MOT_TIM_First Click | GX1: MIN_DYN_WFI_MOT_TIM_Last Click | GY1: MIN_DYN_WFI_MOT_TIM_Page Submit | GZ1: MIN_DYN_WFI_MOT_TIM_Click Count | HA1: MIN_DYN_IWO_MOT_VID | HB1: MIN_DYN_IWO_MOT_CON | HC1: MIN_DYN_IWO_MOT_TIM_First Click | HD1: MIN_DYN_IWO_MOT_TIM_Last Click | HE1: MIN_DYN_IWO_MOT_TIM_Page Submit | HF1: MIN_DYN_IWO_MOT_TIM_Click Count | HG1: MIN_DYN_NH_MOT_VID | HH1: MIN_DYN_NH_MOT_CON | HI1: MIN_DYN_NH_MOT_TIM_First Click | HJ1: MIN_DYN_NH_MOT_TIM_Last Click | HK1: MIN_DYN_NH_MOT_TIM_Page Submit | HL1: MIN_DYN_NH_MOT_TIM_Click Count | HM1: aspects_waiting | HN1: should_have_waitin | HO1: aspects_anapin | HP1: should_have_anapin | HQ1: aspects_foundpin | HR1: should_have_foundpin | HS1: aspects_error | HT1: should_have_error | HU1: aspects_confus | HV1: should_have_confused | HW1: final_feedback | HX1: email_capture | HY1: SectionCounter | HZ1: GroupOrder | IA1: VideoCounter | IB1: Create New Field or Choose From Dropdown... | IC1: Q_DataPolicyViolations
A2: Start Date | B2: End Date | C2: Response Type | D2: IP Address | E2: Progress | F2: Duration (in seconds) | G2: Finished | H2: Recorded Date | I2: Response ID | J2: Recipient Last Name | K2: Recipient First Name | L2: Recipient Email | M2: External Data Reference | N2: Location Latitude | O2: Location Longitude | P2: Distribution Channel | Q2: User Language | R2: Q_RecaptchaScore | S2: I consent to the following: - Provide non-identifying personal data (age, field of work, etc.) | T2: I consent to the following: - Watch and provide feedback on videos of expressive robots | U2: I consent to the following: - Answer a questionnaire regarding the videos of robots | V2: I consent to the following: - Have my non-identifying data published in academic publications and shared in online data repositories | W2: What is your current industry of occupation? | X2: Do you currently or have you previously owned any pets? | Y2: How often do you... - Interact with everyday technology (e.g. use a smartphone, computer or tablet) | Z2: How often do you... - Observe or interact with robots at home (e.g. supervise a vacuum robot) | AA2: How often do you... - Observe or interact with robots at work (e.g. collaborativly pack a box with a robot arm) | AB2: How often do you... - Observe or interact with robots in public (e.g. observe a grocery store cleaning robot) | AC2: Video [Field-VideoCounter]: Watch the video below and indicate which robot state you think Calcifer is communicating. | AD2: Indicate your confidence in your response: | AE2: Timing - First Click | AF2: Timing - Last Click | AG2: Timing - Page Submit | AH2: Timing - Click Count | AI2: Video [Field-VideoCounter]: Watch the video below and indicate which robot state you think Calcifer is communicating. | AJ2: Indicate your confidence in your response: | AK2: Timing - First Click | AL2: Timing - Last Click | AM2: Timing - Page Submit | AN2: Timing - Click Count | AO2: Video [Field-VideoCounter]: Watch the video below and indicate which robot state you think Calcifer is communicating. | AP2: Indicate your confidence in your response: | AQ2: Timing - First Click | AR2: Timing - Last Click | AS2: Timing - Page Submit | AT2: Timing - Click Count | AU2: Video [Field-VideoCounter]: Watch the video below and indicate which robot state you think Calcifer is communicating. | AV2: Indicate your confidence in your response: | AW2: Timing - First Click | AX2: Timing - Last Click | AY2: Timing - Page Submit | AZ2: Timing - Click Count | BA2: Video [Field-VideoCounter]: Watch the video below and indicate which robot state you think Calcifer is communicating. | BB2: Indicate your confidence in your response: | BC2: Timing - First Click | BD2: Timing - Last Click | BE2: Timing - Page Submit | BF2: Timing - Click Count | BG2: Video [Field-VideoCounter]: Watch the video below and indicate which robot state you think Calcifer is communicating. | BH2: Indicate your confidence in your response: | BI2: Timing - First Click | BJ2: Timing - Last Click | BK2: Timing - Page Submit | BL2: Timing - Click Count | BM2: Video [Field-VideoCounter]: Watch the video below and indicate which robot state you think Calcifer is communicating. | BN2: Indicate your confidence in your response: | BO2: Timing - First Click | BP2: Timing - Last Click | BQ2: Timing - Page Submit | BR2: Timing - Click Count | BS2: Video [Field-VideoCounter]: Watch the video below and indicate which robot state you think Calcifer is communicating. | BT2: Indicate your confidence in your response: | BU2: Timing - First Click | BV2: Timing - Last Click | BW2: Timing - Page Submit | BX2: Timing - Click Count | BY2: Video [Field-VideoCounter]: Watch the video below and indicate which robot state you think Calcifer is communicating. | BZ2: Indicate your confidence in your response: | CA2: Timing - First Click | CB2: Timing - Last Click | CC2: Timing - Page Submit | CD2: Timing - Click Count | CE2: Video [Field-VideoCounter]: Watch the video below and indicate which robot state you think Calcifer is communicating. | CF2: Indicate your confidence in your response: | CG2: Timing - First Click | CH2: Timing - Last Click | CI2: Timing - Page Submit | CJ2: Timing - Click Count | CK2: Video [Field-VideoCounter]: Watch the video below and indicate which robot state you think Calcifer is communicating. | CL2: Indicate your confidence in your response: | CM2: Timing - First Click | CN2: Timing - Last Click | CO2: Timing - Page Submit | CP2: Timing - Click Count | CQ2: Video [Field-VideoCounter]: Watch the video below and indicate which robot state you think Calcifer is communicating. | CR2: Indicate your confidence in your response: | CS2: Timing - First Click | CT2: Timing - Last Click | CU2: Timing - Page Submit | CV2: Timing - Click Count | CW2: Video [Field-VideoCounter]: Watch the video below and indicate which robot state you think Calcifer is communicating. | CX2: Indicate your confidence in your response: | CY2: Timing - First Click | CZ2: Timing - Last Click | DA2: Timing - Page Submit | DB2: Timing - Click Count | DC2: Video [Field-VideoCounter]: Watch the video below and indicate which robot state you think Calcifer is communicating. | DD2: Indicate your confidence in your response: | DE2: Timing - First Click | DF2: Timing - Last Click | DG2: Timing - Page Submit | DH2: Timing - Click Count | DI2: Video [Field-VideoCounter]: Watch the video below and indicate which robot state you think Calcifer is communicating. | DJ2: Indicate your confidence in your response: | DK2: Timing - First Click | DL2: Timing - Last Click | DM2: Timing - Page Submit | DN2: Timing - Click Count | DO2: Video [Field-VideoCounter]: Watch the video below and indicate which robot state you think Calcifer is communicating. | DP2: Indicate your confidence in your response: | DQ2: Timing - First Click | DR2: Timing - Last Click | DS2: Timing - Page Submit | DT2: Timing - Click Count | DU2: Video [Field-VideoCounter]: Watch the video below and indicate which robot state you think Calcifer is communicating. | DV2: Indicate your confidence in your response: | DW2: Timing - First Click | DX2: Timing - Last Click | DY2: Timing - Page Submit | DZ2: Timing - Click Count | EA2: Video [Field-VideoCounter]: Watch the video below and indicate which robot state you think Calcifer is communicating. | EB2: Indicate your confidence in your response: | EC2: Timing - First Click | ED2: Timing - Last Click | EE2: Timing - Page Submit | EF2: Timing - Click Count | EG2: Video [Field-VideoCounter]: Watch the video below and indicate which robot state you think Calcifer is communicating. | EH2: Indicate your confidence in your response: | EI2: Timing - First Click | EJ2: Timing - Last Click | EK2: Timing - Page Submit | EL2: Timing - Click Count | EM2: Video [Field-VideoCounter]: Watch the video below and indicate which robot state you think Calcifer is communicating. | EN2: Indicate your confidence in your response: | EO2: Timing - First Click | EP2: Timing - Last Click | EQ2: Timing - Page Submit | ER2: Timing - Click Count | ES2: Video [Field-VideoCounter]: Watch the video below and indicate which robot state you think Calcifer is communicating. | ET2: Indicate your confidence in your response: | EU2: Timing - First Click | EV2: Timing - Last Click | EW2: Timing - Page Submit | EX2: Timing - Click Count | EY2: Video [Field-VideoCounter]: Watch the video below and indicate which robot state you think Calcifer is communicating. | EZ2: Indicate your confidence in your response: | FA2: Timing - First Click | FB2: Timing - Last Click | FC2: Timing - Page Submit | FD2: Timing - Click Count | FE2: Video [Field-VideoCounter]: Watch the video below and indicate which robot state you think Calcifer is communicating. | FF2: Indicate your confidence in your response: | FG2: Timing - First Click | FH2: Timing - Last Click | FI2: Timing - Page Submit | FJ2: Timing - Click Count | FK2: Video [Field-VideoCounter]: Watch the video below and indicate which robot state you think Calcifer is communicating. | FL2: Indicate your confidence in your response: | FM2: Timing - First Click | FN2: Timing - Last Click | FO2: Timing - Page Submit | FP2: Timing - Click Count | FQ2: Video [Field-VideoCounter]: Watch the video below and indicate which robot state you think Calcifer is communicating. | FR2: Indicate your confidence in your response: | FS2: Timing - First Click | FT2: Timing - Last Click | FU2: Timing - Page Submit | FV2: Timing - Click Count | FW2: Video [Field-VideoCounter]: Watch the video below and indicate which robot state you think Calcifer is communicating. | FX2: Indicate your confidence in your response: | FY2: Timing - First Click | FZ2: Timing - Last Click | GA2: Timing - Page Submit | GB2: Timing - Click Count | GC2: Video [Field-VideoCounter]: Watch the video below and indicate which robot state you think Calcifer is communicating. | GD2: Indicate your confidence in your response: | GE2: Timing - First Click | GF2: Timing - Last Click | GG2: Timing - Page Submit | GH2: Timing - Click Count | GI2: Video [Field-VideoCounter]: Watch the video below and indicate which robot state you think Calcifer is communicating. | GJ2: Indicate your confidence in your response: | GK2: Timing - First Click | GL2: Timing - Last Click | GM2: Timing - Page Submit | GN2: Timing - Click Count | GO2: Video [Field-VideoCounter]: Watch the video below and indicate which robot state you think Calcifer is communicating. | GP2: Indicate your confidence in your response: | GQ2: Timing - First Click | GR2: Timing - Last Click | GS2: Timing - Page Submit | GT2: Timing - Click Count | GU2: Video [Field-VideoCounter]: Watch the video below and indicate which robot state you think Calcifer is communicating. | GV2: Indicate your confidence in your response: | GW2: Timing - First Click | GX2: Timing - Last Click | GY2: Timing - Page Submit | GZ2: Timing - Click Count | HA2: Video [Field-VideoCounter]: Watch the video below and indicate which robot state you think Calcifer is communicating. | HB2: Indicate your confidence in your response: | HC2: Timing - First Click | HD2: Timing - Last Click | HE2: Timing - Page Submit | HF2: Timing - Click Count | HG2: Video [Field-VideoCounter]: Watch the video below and indicate which robot state you think Calcifer is communicating. | HH2: Indicate your confidence in your response: | HI2: Timing - First Click | HJ2: Timing - Last Click | HK2: Timing - Page Submit | HL2: Timing - Click Count | HM2: Based on what you saw in the videos, what aspects of the robot's body language did you associate with the state Waiting for Input? | HN2: Describe what you think the robot should have done to express the state Waiting for Input? | HO2: Based on what you saw in the videos, what aspects of the robot's body language did you associate with the state Analyzing Pinecone? | HP2: Describe what you think the robot should have done to express the state Analyzing Pinecone? | HQ2: Based on what you saw in the videos, what aspects of the robot's body language did you associate with the state Found Pinecone? | HR2: Describe what you think the robot should have done to express the state Found Pinecone? | HS2: Based on what you saw in the videos, what aspects of the robot's body language did you associate with the state Error? | HT2: Describe what you think the robot should have done to express the state Error? | HU2: Based on what you saw in the videos, what aspects of the robot's body language did you associate with the state Confused? | HV2: Describe what you think the robot should have done to express the state Confused? | HW2: Optional | Is there any other feedback you’d like to provide related to the robot, this study, or this research in general? | HX2: Optional | If you are interested in participating in our future online studies, please provide your email below. This data will not be shared with anyone or used for any other purpose beyond contacting you regarding our future research studies. Your response has not been submitted yet. Hit next to continue. | HY2: SectionCounter | HZ2: GroupOrder | IA2: VideoCounter | IB2: Create New Field or Choose From Dropdown... | IC2: Q_DataPolicyViolations
A3: 45739.275 | B3: 45739.289 | C3: IP Address | D3: 185.153.179.23 | E3: 100 | F3: 1198 | G3: True | H3: 45739.289 | I3: R_7riMjeGOoUZ7EKu | N3: 49.2476 | O3: -123.1234 | P3: anonymous | Q3: EN | R3: 1 | S3: Yes | T3: Yes | U3: Yes | V3: Yes | W3: Academic (e.g. student, teacher) | X3: Dog | Y3: Nearly every day or more | Z3: Never | AA3: At least once per week | AB3: Never | AC3: Waiting for Input | Calcifer is in standby mode, waiting for a command from you. | AD3: Somewhat Confident | AE3: 10.134 | AF3: 12.068 | AG3: 12.728 | AH3: 2 | AI3: Analyzing Pinecone | Calcifer is analyzing a target pinecone to assess its size. | AJ3: Fully Confident | AK3: 10.183 | AL3: 11.6 | AM3: 12.132 | AN3: 2 | AO3: Analyzing Pinecone | Calcifer is analyzing a target pinecone to assess its size. | AP3: Fully Confident | AQ3: 6.594 | AR3: 7.73 | AS3: 8.858 | AT3: 2 | AU3: Error | Calcifer is signalling to you that it is experiencing a critical error. | AV3: Very Confident | AW3: 6.301 | AX3: 7.462 | AY3: 8.692 | AZ3: 2 | BA3: Error | Calcifer is signalling to you that it is experiencing a critical error. | BB3: Very Confident | BC3: 6.77 | BD3: 8.917 | BE3: 9.568 | BF3: 2 | BG3: Waiting for Input | Calcifer is in standby mode, waiting for a command from you. | BH3: Somewhat Confident | BI3: 12.278 | BJ3: 14.422 | BK3: 15.058 | BL3: 3 | BM3: Analyzing Pinecone | Calcifer is analyzing a target pinecone to assess its size. | BN3: Fully Confident | BO3: 10.258 | BP3: 11.574 | BQ3: 12.039 | BR3: 2 | BS3: Waiting for Input | Calcifer is in standby mode, waiting for a command from you. | BT3: Not Very Confident | BU3: 16.927 | BV3: 18.072 | BW3: 19.263 | BX3: 2 | BY3: Error | Calcifer is signalling to you that it is experiencing a critical error. | BZ3: Very Confident | CA3: 10.674 | CB3: 16.263 | CC3: 16.901 | CD3: 2 | CE3: Confused | Calcifer is signalling to you that it is confused and unsure what to do. | CF3: Somewhat Confident | CG3: 7.444 | CH3: 8.334 | CI3: 9.125 | CJ3: 2 | CK3: Waiting for Input | Calcifer is in standby mode, waiting for a command from you. | CL3: Very Confident | CM3: 7.006 | CN3: 8.336 | CO3: 8.91 | CP3: 2 | CQ3: Analyzing Pinecone | Calcifer is analyzing a target pinecone to assess its size. | CR3: Fully Confident | CS3: 51.029 | CT3: 52.383 | CU3: 52.933 | CV3: 2 | CW3: Waiting for Input | Calcifer is in standby mode, waiting for a command from you. | CX3: Somewhat Confident | CY3: 21.354 | CZ3: 27.242 | DA3: 27.948 | DB3: 2 | DC3: Error | Calcifer is signalling to you that it is experiencing a critical error. | DD3: Very Confident | DE3: 8.463 | DF3: 14.501 | DG3: 20.196 | DH3: 2 | DI3: Confused | Calcifer is signalling to you that it is confused and unsure what to do. | DJ3: Very Confident | DK3: 9 | DL3: 11.236 | DM3: 11.863 | DN3: 2 | DO3: Waiting for Input | Calcifer is in standby mode, waiting for a command from you. | DP3: Very Confident | DQ3: 7.126 | DR3: 8.409 | DS3: 9.249 | DT3: 2 | DU3: Analyzing Pinecone | Calcifer is analyzing a target pinecone to assess its size. | DV3: Very Confident | DW3: 5.884 | DX3: 7.049 | DY3: 8.814 | DZ3: 2 | EA3: Found Pinecone | Calcifer is signalling to you that it has found a suitable pinecone. | EB3: Very Confident | EC3: 5.818 | ED3: 17.806 | EE3: 21.104 | EF3: 4 | EG3: Error | Calcifer is signalling to you that it is experiencing a critical error. | EH3: Somewhat Confident | EI3: 9.812 | EJ3: 24.411 | EK3: 24.908 | EL3: 7 | EM3: Confused | Calcifer is signalling to you that it is confused and unsure what to do. | EN3: Very Confident | EO3: 6.649 | EP3: 7.635 | EQ3: 8.647 | ER3: 2 | ES3: Waiting for Input | Calcifer is in standby mode, waiting for a command from you. | ET3: Somewhat Confident | EU3: 20.294 | EV3: 30.279 | EW3: 30.877 | EX3: 3 | EY3: Interacting with Pinecone | Calcifer is interacting with a target pinecone. | EZ3: Fully Confident | FA3: 7.306 | FB3: 9.861 | FC3: 10.574 | FD3: 2 | FE3: Needs Help | Calcifer is signalling to you that it needs your help. | FF3: Not Very Confident | FG3: 69.899 | FH3: 89.116 | FI3: 90.136 | FJ3: 2 | FK3: Waiting for Input | Calcifer is in standby mode, waiting for a command from you. | FL3: Very Confident | FM3: 8.533 | FN3: 11.198 | FO3: 11.937 | FP3: 2 | FQ3: Interacting with Pinecone | Calcifer is interacting with a target pinecone. | FR3: Fully Confident | FS3: 22.188 | FT3: 23.456 | FU3: 24.548 | FV3: 2 | FW3: Needs Help | Calcifer is signalling to you that it needs your help. | FX3: Not Very Confident | FY3: 8.579 | FZ3: 14.046 | GA3: 14.776 | GB3: 4 | GC3: Waiting for Input | Calcifer is in standby mode, waiting for a command from you. | GD3: Very Confident | GE3: 8.736 | GF3: 11.89 | GG3: 12.894 | GH3: 3 | GI3: Interacting with Pinecone | Calcifer is interacting with a target pinecone. | GJ3: Fully Confident | GK3: 6.149 | GL3: 7.02 | GM3: 8.861 | GN3: 2 | GO3: Needs Help | Calcifer is signalling to you that it needs your help. | GP3: Very Confident | GQ3: 44.91 | GR3: 49.554 | GS3: 50.612 | GT3: 5 | GU3: Needs Help | Calcifer is signalling to you that it needs your help. | GV3: Very Confident | GW3: 9.74 | GX3: 12.873 | GY3: 13.939 | GZ3: 2 | HA3: Interacting with Pinecone | Calcifer is interacting with a target pinecone. | HB3: Fully Confident | HC3: 8.302 | HD3: 10.009 | HE3: 12.643 | HF3: 2 | HG3: Waiting for Input | Calcifer is in standby mode, waiting for a command from you. | HH3: Not Very Confident | HI3: 10.275 | HJ3: 16.181 | HK3: 17.468 | HL3: 4 | HM3: Looking at me and not moving | HN3: Looking at me and not moving | HO3: Was crouching down to look at the pinecone | HP3: Crouching down and looking at a pinecone | HQ3: Looking at me while in front of a pinecone | HR3: Maybe a distinctive movement to get my attention | HS3: Shaking | HT3: Shaking or lying down | HU3: Tilting its head and shoulder | HV3: Tilting its head and shoulder | HX3: colleen.ogilvie@ucalgary.ca | HY3: 2 | IA3: 20
A4: 45740.72 | B4: 45740.735 | C4: IP Address | D4: 106.70.72.222 | E4: 100 | F4: 1310 | G4: True | H4: 45740.735 | I4: R_4WAuQLonzRKrSfC | N4: -37.8333 | O4: 145.2375 | P4: anonymous | Q4: EN | R4: 1 | S4: Yes | T4: Yes | U4: Yes | V4: Yes | W4: Academic (e.g. student, teacher) | X4: Dog,Fish | Y4: Nearly every day or more | Z4: Never | AA4: At least once per week | AB4: Less than once per month | AC4: Waiting for Input | Calcifer is in standby mode, waiting for a command from you. | AD4: Somewhat Confident | AE4: 8.701 | AF4: 11.013 | AG4: 11.898 | AH4: 2 | AI4: Analyzing Pinecone | Calcifer is analyzing a target pinecone to assess its size. | AJ4: Very Confident | AK4: 6.164 | AL4: 16.862 | AM4: 17.936 | AN4: 3 | AO4: Found Pinecone | Calcifer is signalling to you that it has found a suitable pinecone. | AP4: Somewhat Confident | AQ4: 10.121 | AR4: 22.819 | AS4: 24.325 | AT4: 5 | AU4: Error | Calcifer is signalling to you that it is experiencing a critical error. | AV4: Somewhat Confident | AW4: 6.797 | AX4: 8.347 | AY4: 9.368 | AZ4: 2 | BA4: Confused | Calcifer is signalling to you that it is confused and unsure what to do. | BB4: Very Confident | BC4: 14.658 | BD4: 16.894 | BE4: 17.218 | BF4: 3 | BG4: Waiting for Input | Calcifer is in standby mode, waiting for a command from you. | BH4: Not Very Confident | BI4: 11.268 | BJ4: 13.087 | BK4: 13.824 | BL4: 4 | BM4: Analyzing Pinecone | Calcifer is analyzing a target pinecone to assess its size. | BN4: Very Confident | BO4: 17.611 | BP4: 18.806 | BQ4: 19.833 | BR4: 2 | BS4: Waiting for Input | Calcifer is in standby mode, waiting for a command from you. | BT4: Somewhat Confident | BU4: 12.226 | BV4: 14.433 | BW4: 15.883 | BX4: 2 | BY4: Confused | Calcifer is signalling to you that it is confused and unsure what to do. | BZ4: Somewhat Confident | CA4: 22.498 | CB4: 30.413 | CC4: 31.655 | CD4: 4 | CE4: Error | Calcifer is signalling to you that it is experiencing a critical error. | CF4: Somewhat Confident | CG4: 9.416 | CH4: 10.911 | CI4: 11.521 | CJ4: 2 | CK4: Waiting for Input | Calcifer is in standby mode, waiting for a command from you. | CL4: Not Very Confident | CM4: 45.296 | CN4: 59.214 | CO4: 59.964 | CP4: 3 | CQ4: Analyzing Pinecone | Calcifer is analyzing a target pinecone to assess its size. | CR4: Very Confident | CS4: 14.741 | CT4: 18.647 | CU4: 18.947 | CV4: 4 | CX4: Somewhat Confident | CY4: 19.124 | CZ4: 28.621 | DA4: 30.481 | DB4: 6 | DC4: Found Pinecone | Calcifer is signalling to you that it has found a suitable pinecone. | DD4: Somewhat Confident | DE4: 47.688 | DF4: 49.097 | DG4: 50.266 | DH4: 2 | DI4: Confused | Calcifer is signalling to you that it is confused and unsure what to do. | DJ4: Somewhat Confident | DK4: 10.718 | DL4: 12.077 | DM4: 14.022 | DN4: 2 | DO4: Waiting for Input | Calcifer is in standby mode, waiting for a command from you. | DP4: Somewhat Confident | DQ4: 58.468 | DR4: 60.373 | DS4: 61.119 | DT4: 3 | DU4: Analyzing Pinecone | Calcifer is analyzing a target pinecone to assess its size. | DV4: Very Confident | DW4: 39.923 | DX4: 47.718 | DY4: 48.691 | DZ4: 4 | EA4: Confused | Calcifer is signalling to you that it is confused and unsure what to do. | EB4: Somewhat Confident | EC4: 18.674 | ED4: 20.186 | EE4: 21.273 | EF4: 2 | EG4: Error | Calcifer is signalling to you that it is experiencing a critical error. | EH4: Very Confident | EI4: 9.452 | EJ4: 14.918 | EK4: 15.62 | EL4: 3 | EM4: Error | Calcifer is signalling to you that it is experiencing a critical error. | EN4: Not Very Confident | EO4: 47.974 | EP4: 50.721 | EQ4: 51.693 | ER4: 3 | ES4: Waiting for Input | Calcifer is in standby mode, waiting for a command from you. | ET4: Somewhat Confident | EU4: 128.747 | EV4: 131.763 | EW4: 132.613 | EX4: 4 | EY4: Interacting with Pinecone | Calcifer is interacting with a target pinecone. | EZ4: Fully Confident | FA4: 8.652 | FB4: 10.275 | FC4: 10.496 | FD4: 3 | FE4: Needs Help | Calcifer is signalling to you that it needs your help. | FF4: Fully Confident | FG4: 4.39 | FH4: 8.797 | FI4: 10.472 | FJ4: 3 | FK4: Waiting for Input | Calcifer is in standby mode, waiting for a command from you. | FL4: Fully Confident | FM4: 8.127 | FN4: 8.99 | FO4: 9.45 | FP4: 2 | FQ4: Interacting with Pinecone | Calcifer is interacting with a target pinecone. | FR4: Very Confident | FS4: 12.666 | FT4: 14.68 | FU4: 15.239 | FV4: 2 | FW4: Needs Help | Calcifer is signalling to you that it needs your help. | FX4: Fully Confident | FY4: 4.428 | FZ4: 8.893 | GA4: 9.131 | GB4: 6 | GC4: Waiting for Input | Calcifer is in standby mode, waiting for a command from you. | GD4: Very Confident | GE4: 12.575 | GF4: 17.531 | GG4: 18.158 | GH4: 2 | GI4: Interacting with Pinecone | Calcifer is interacting with a target pinecone. | GJ4: Very Confident | GK4: 7.301 | GL4: 8.863 | GM4: 9.354 | GN4: 2 | GO4: Needs Help | Calcifer is signalling to you that it needs your help. | GP4: Fully Confident | GQ4: 4.382 | GR4: 6.227 | GS4: 8.698 | GT4: 2 | GU4: Waiting for Input | Calcifer is in standby mode, waiting for a command from you. | GV4: Very Confident | GW4: 8.192 | GX4: 10.185 | GY4: 10.417 | GZ4: 3 | HA4: Interacting with Pinecone | Calcifer is interacting with a target pinecone. | HB4: Fully Confident | HC4: 7.971 | HD4: 11.324 | HE4: 11.784 | HF4: 3 | HG4: Waiting for Input | Calcifer is in standby mode, waiting for a command from you. | HH4: Very Confident | HI4: 5.234 | HJ4: 9.539 | HK4: 10.054 | HL4: 2 | HM4: When the robot was still but not facing the pine cones | HN4: Point it's head up at the user | HO4: When the robot was looking down directly at the pine cone | HP4: When the robot was looking down directly at the pine cone | HQ4: When the robot was looking up from the pinecones | HR4: When the robot was looking up from the pinecones | HS4: When the robot was shaking a lot and the body tilt was not level | HT4: A lot of shaky movement, ideally pointing at the user | HU4: When the robot was tilted away from the pinecones | HV4: When the robot was tilted away from the pinecones | HY4: 2 | IA4: 12
A5: 45740.927 | B5: 45740.955 | C5: IP Address | D5: 1.145.210.32 | E5: 100 | F5: 2384 | G5: True | H5: 45740.955 | I5: R_47j7XUtfSdILY1E | N5: -37.8159 | O5: 144.9669 | P5: anonymous | Q5: EN | R5: 0.80000001 | S5: Yes | T5: Yes | U5: Yes | V5: Yes | W5: Academic (e.g. student, teacher) | X5: Cat | Y5: Nearly every day or more | Z5: Never | AA5: A few times per month | AB5: Less than once per month | AC5: Waiting for Input | Calcifer is in standby mode, waiting for a command from you. | AD5: Very Confident | AE5: 6.636 | AF5: 9.368 | AG5: 9.711 | AH5: 3 | AI5: Analyzing Pinecone | Calcifer is analyzing a target pinecone to assess its size. | AJ5: Very Confident | AK5: 5.729 | AL5: 6.657 | AM5: 8.859 | AN5: 2 | AO5: Analyzing Pinecone | Calcifer is analyzing a target pinecone to assess its size. | AP5: Very Confident | AQ5: 5.031 | AR5: 8.978 | AS5: 9.595 | AT5: 2 | AU5: Error | Calcifer is signalling to you that it is experiencing a critical error. | AV5: Somewhat Confident | AW5: 24.637 | AX5: 48.817 | AY5: 51.74 | AZ5: 3 | BA5: Error | Calcifer is signalling to you that it is experiencing a critical error. | BB5: Not Very Confident | BC5: 25.605 | BD5: 26.597 | BE5: 27.856 | BF5: 3 | BG5: Waiting for Input | Calcifer is in standby mode, waiting for a command from you. | BH5: Very Confident | BI5: 8.711 | BJ5: 10.858 | BK5: 11.408 | BL5: 2 | BM5: Analyzing Pinecone | Calcifer is analyzing a target pinecone to assess its size. | BN5: Very Confident | BO5: 5.05 | BP5: 13.986 | BQ5: 14.981 | BR5: 2 | BS5: Analyzing Pinecone | Calcifer is analyzing a target pinecone to assess its size. | BT5: Not Very Confident | BU5: 12.53 | BV5: 17.978 | BW5: 23.62 | BX5: 2 | BY5: Error | Calcifer is signalling to you that it is experiencing a critical error. | BZ5: Not Very Confident | CA5: 9.439 | CB5: 10.403 | CC5: 11.641 | CD5: 2 | CE5: Confused | Calcifer is signalling to you that it is confused and unsure what to do. | CF5: Somewhat Confident | CG5: 6.903 | CH5: 15.758 | CI5: 19.6 | CJ5: 8 | CK5: Waiting for Input | Calcifer is in standby mode, waiting for a command from you. | CL5: Very Confident | CM5: 31.07 | CN5: 32.753 | CO5: 33.097 | CP5: 3 | CQ5: Analyzing Pinecone | Calcifer is analyzing a target pinecone to assess its size. | CR5: Very Confident | CS5: 9.526 | CT5: 11.737 | CU5: 13.456 | CV5: 2 | CW5: Analyzing Pinecone | Calcifer is analyzing a target pinecone to assess its size. | CX5: Somewhat Confident | CY5: 10.98 | CZ5: 30.835 | DA5: 31.97 | DB5: 5 | DC5: Confused | Calcifer is signalling to you that it is confused and unsure what to do. | DD5: Somewhat Confident | DE5: 92.203 | DF5: 118.602 | DG5: 120.024 | DH5: 3 | DI5: Confused | Calcifer is signalling to you that it is confused and unsure what to do. | DJ5: Somewhat Confident | DK5: 13.856 | DL5: 17.888 | DM5: 21.558 | DN5: 3 | DO5: Waiting for Input | Calcifer is in standby mode, waiting for a command from you. | DP5: Very Confident | DQ5: 40.87 | DR5: 43.009 | DS5: 45.998 | DT5: 2 | DU5: Analyzing Pinecone | Calcifer is analyzing a target pinecone to assess its size. | DV5: Very Confident | DW5: 6.997 | DX5: 8.877 | DY5: 9.815 | DZ5: 2 | EA5: Found Pinecone | Calcifer is signalling to you that it has found a suitable pinecone. | EB5: Not Very Confident | EC5: 20.923 | ED5: 22.027 | EE5: 22.658 | EF5: 2 | EG5: Error | Calcifer is signalling to you that it is experiencing a critical error. | EH5: Not Very Confident | EI5: 14.647 | EJ5: 16.154 | EK5: 16.993 | EL5: 2 | EM5: Confused | Calcifer is signalling to you that it is confused and unsure what to do. | EN5: Somewhat Confident | EO5: 93.908 | EP5: 98.892 | EQ5: 100.121 | ER5: 2 | ES5: Waiting for Input | Calcifer is in standby mode, waiting for a command from you. | ET5: Very Confident | EU5: 8.909 | EV5: 10.237 | EW5: 13.347 | EX5: 2 | EY5: Interacting with Pinecone | Calcifer is interacting with a target pinecone. | EZ5: Fully Confident | FA5: 10.22 | FB5: 11.92 | FC5: 12.514 | FD5: 2 | FF5: Not Confident at All | FG5: 9.282 | FH5: 14.578 | FI5: 15.385 | FJ5: 2 | FK5: Waiting for Input | Calcifer is in standby mode, waiting for a command from you. | FL5: Somewhat Confident | FM5: 8.547 | FN5: 10.94 | FO5: 11.586 | FP5: 2 | FQ5: Interacting with Pinecone | Calcifer is interacting with a target pinecone. | FR5: Fully Confident | FS5: 5.199 | FT5: 10.495 | FU5: 11.33 | FV5: 2 | FW5: Needs Help | Calcifer is signalling to you that it needs your help. | FX5: Not Very Confident | FY5: 27.272 | FZ5: 28.284 | GA5: 29.07 | GB5: 2 | GC5: Waiting for Input | Calcifer is in standby mode, waiting for a command from you. | GD5: Not Very Confident | GE5: 28.674 | GF5: 30.481 | GG5: 32.256 | GH5: 2 | GI5: Interacting with Pinecone | Calcifer is interacting with a target pinecone. | GJ5: Fully Confident | GK5: 6.442 | GL5: 7.674 | GM5: 10 | GN5: 2 | GO5: Needs Help | Calcifer is signalling to you that it needs your help. | GP5: Somewhat Confident | GQ5: 6.913 | GR5: 8.238 | GS5: 9.407 | GT5: 2 | GU5: Needs Help | Calcifer is signalling to you that it needs your help. | GV5: Not Very Confident | GW5: 32.82 | GX5: 38.732 | GY5: 39.634 | GZ5: 2 | HA5: Interacting with Pinecone | Calcifer is interacting with a target pinecone. | HB5: Very Confident | HC5: 9.768 | HD5: 11.081 | HE5: 12.238 | HF5: 2 | HG5: Waiting for Input | Calcifer is in standby mode, waiting for a command from you. | HH5: Not Very Confident | HI5: 36.736 | HJ5: 43.332 | HK5: 46.378 | HL5: 4 | HM5: A neutral state with no motion. I usually associated this state with flat poses and a gaze either not directed at anything or directed at me, waiting for me to give a command. Generally, I was more confident assigning this state to poses that did not have any specific focus, i.e. the pine cones or camera. | HN5: I would expect a neutral pose, with no movement or extended limbs. | HO5: I found this to be the most obvious pose, indicated by the robot looking directly at the pine cones. A tilt towards the pine cones also made this more obvious. | HP5: Looking at the pine cones from close range with raised back legs and lowered front legs was an obvious indication that the robot was analyzing the pine cones. | HQ5: I didn't see many poses that I associated with this state. I think the only pose that I assigned to this group was looking upward while standing in front of the pine cones. | HR5: I would have expected the robot to face me and move its front up and down, almost like an excited dog. Alternatively, moving its gaze between me and the cones repeatedly would have indicated that it was trying to bring them to my attention. | HS5: I mostly associated this state with jittery motions, usually while looking at the camera. | HT5: I think jittery motions are a good way to convey error, possibly in a lowered stance (like a cowering animal). | HU5: I associated this state with a lopsided pose, like a shrugging shoulder. | HV5: I think the shrugging motion was effective, especially while looking at the camera. It gave the impression that the robot was asking a question. | HW5: I think that the poses are good static presentations of the states, but dynamic/repeated motions (such as the one I described for found pinecone) could have been more descriptive. Overall, I think I felt more confident with the first group of videos. It could also be helpful to view the same poses in slightly different contexts (locations, camera angles etc.) to better understand them. I'm not expecting you to make any of these changes, but just some thoughts. A few other notes: some of the videos said 'full screen unavailable', although this wasn't much of an issue. Also, a lot of the videos felt very similar and sometimes the same clip seemed to repeat a few times, not sure if that's intentional or if its randomized though. Finally, if the scenario is the same for the 2 video sets, any need to introduce it twice? It's all looking good though Liam, good luck with the final edits. | HY5: 2 | IA5: 12
A6: 45744.426 | B6: 45744.436 | C6: IP Address | D6: 120.159.76.92 | E6: 100 | F6: 810 | G6: True | H6: 45744.436 | I6: R_4pnywJ4fzDl5YOv | N6: -37.9793 | O6: 145.1297 | P6: anonymous | Q6: EN | R6: 0.5 | S6: Yes | T6: Yes | U6: Yes | V6: Yes | W6: Academic (e.g. student, teacher) | X6: Dog | Y6: Nearly every day or more | Z6: Never | AA6: Less than once per month | AB6: Less than once per month | AC6: Waiting for Input | Calcifer is in standby mode, waiting for a command from you. | AD6: Somewhat Confident | AE6: 7.968 | AF6: 9.601 | AG6: 10.591 | AH6: 2 | AI6: Found Pinecone | Calcifer is signalling to you that it has found a suitable pinecone. | AJ6: Somewhat Confident | AK6: 6.694 | AL6: 8.366 | AM6: 9.449 | AN6: 2 | AO6: Analyzing Pinecone | Calcifer is analyzing a target pinecone to assess its size. | AP6: Very Confident | AQ6: 6.351 | AR6: 11.339 | AS6: 12.26 | AT6: 2 | AU6: Error | Calcifer is signalling to you that it is experiencing a critical error. | AV6: Somewhat Confident | AW6: 6.509 | AX6: 10.23 | AY6: 11.144 | AZ6: 3 | BA6: Error | Calcifer is signalling to you that it is experiencing a critical error. | BB6: Somewhat Confident | BC6: 7.384 | BD6: 9.386 | BE6: 9.787 | BF6: 3 | BG6: Waiting for Input | Calcifer is in standby mode, waiting for a command from you. | BH6: Very Confident | BI6: 9.26 | BJ6: 12.16 | BK6: 12.863 | BL6: 2 | BM6: Analyzing Pinecone | Calcifer is analyzing a target pinecone to assess its size. | BN6: Somewhat Confident | BO6: 10.015 | BP6: 11.457 | BQ6: 13.064 | BR6: 2 | BS6: Waiting for Input | Calcifer is in standby mode, waiting for a command from you. | BT6: Not Very Confident | BU6: 7.449 | BV6: 9.972 | BW6: 10.747 | BX6: 2 | BY6: Confused | Calcifer is signalling to you that it is confused and unsure what to do. | BZ6: Not Very Confident | CA6: 15.501 | CB6: 17.5 | CC6: 18.602 | CD6: 2 | CE6: Confused | Calcifer is signalling to you that it is confused and unsure what to do. | CF6: Somewhat Confident | CG6: 6.483 | CH6: 7.884 | CI6: 9.131 | CJ6: 2 | CK6: Waiting for Input | Calcifer is in standby mode, waiting for a command from you. | CL6: Somewhat Confident | CM6: 6.458 | CN6: 8.512 | CO6: 9.273 | CP6: 2 | CQ6: Found Pinecone | Calcifer is signalling to you that it has found a suitable pinecone. | CR6: Somewhat Confident | CS6: 8.003 | CT6: 10.977 | CU6: 11.714 | CV6: 2 | CW6: Waiting for Input | Calcifer is in standby mode, waiting for a command from you. | CX6: Somewhat Confident | CY6: 6.124 | CZ6: 7.281 | DA6: 9.088 | DB6: 2 | DC6: Error | Calcifer is signalling to you that it is experiencing a critical error. | DD6: Somewhat Confident | DE6: 7.181 | DF6: 8.412 | DG6: 9.431 | DH6: 2 | DI6: Waiting for Input | Calcifer is in standby mode, waiting for a command from you. | DJ6: Somewhat Confident | DK6: 7.245 | DL6: 8.701 | DM6: 11.848 | DN6: 2 | DO6: Waiting for Input | Calcifer is in standby mode, waiting for a command from you. | DP6: Somewhat Confident | DQ6: 6.81 | DR6: 8.302 | DS6: 9.489 | DT6: 2 | DU6: Found Pinecone | Calcifer is signalling to you that it has found a suitable pinecone. | DV6: Somewhat Confident | DW6: 7.037 | DX6: 12.634 | DY6: 13.508 | DZ6: 2 | EA6: Waiting for Input | Calcifer is in standby mode, waiting for a command from you. | EB6: Somewhat Confident | EC6: 8.726 | ED6: 10.089 | EE6: 10.902 | EF6: 2 | EG6: Error | Calcifer is signalling to you that it is experiencing a critical error. | EH6: Not Very Confident | EI6: 7.558 | EJ6: 10.206 | EK6: 10.973 | EL6: 2 | EM6: Waiting for Input | Calcifer is in standby mode, waiting for a command from you. | EN6: Somewhat Confident | EO6: 8.12 | EP6: 9.47 | EQ6: 10.367 | ER6: 2 | ES6: Waiting for Input | Calcifer is in standby mode, waiting for a command from you. | ET6: Somewhat Confident | EU6: 8.336 | EV6: 9.65 | EW6: 10.483 | EX6: 2 | EY6: Interacting with Pinecone | Calcifer is interacting with a target pinecone. | EZ6: Very Confident | FA6: 8.942 | FB6: 12.161 | FC6: 13.344 | FD6: 2 | FE6: Interacting with Pinecone | Calcifer is interacting with a target pinecone. | FF6: Somewhat Confident | FG6: 7.384 | FH6: 10.338 | FI6: 11.536 | FJ6: 3 | FK6: Waiting for Input | Calcifer is in standby mode, waiting for a command from you. | FL6: Somewhat Confident | FM6: 6.013 | FN6: 7.013 | FO6: 8.97 | FP6: 2 | FQ6: Waiting for Input | Calcifer is in standby mode, waiting for a command from you. | FR6: Somewhat Confident | FS6: 12.679 | FT6: 15.04 | FU6: 18.83 | FV6: 2 | FW6: Interacting with Pinecone | Calcifer is interacting with a target pinecone. | FX6: Somewhat Confident | FY6: 19.612 | FZ6: 22.427 | GA6: 23.643 | GB6: 2 | GC6: Waiting for Input | Calcifer is in standby mode, waiting for a command from you. | GD6: Somewhat Confident | GE6: 7.842 | GF6: 8.701 | GG6: 10.311 | GH6: 2 | GI6: Interacting with Pinecone | Calcifer is interacting with a target pinecone. | GJ6: Somewhat Confident | GK6: 8.259 | GL6: 10.123 | GM6: 11.65 | GN6: 2 | GO6: Waiting for Input | Calcifer is in standby mode, waiting for a command from you. | GP6: Somewhat Confident | GQ6: 6.232 | GR6: 9.056 | GS6: 9.844 | GT6: 2 | GU6: Waiting for Input | Calcifer is in standby mode, waiting for a command from you. | GV6: Somewhat Confident | GW6: 10.388 | GX6: 11.245 | GY6: 12.594 | GZ6: 2 | HA6: Interacting with Pinecone | Calcifer is interacting with a target pinecone. | HB6: Very Confident | HC6: 7.436 | HD6: 8.711 | HE6: 9.999 | HF6: 2 | HG6: Waiting for Input | Calcifer is in standby mode, waiting for a command from you. | HH6: Somewhat Confident | HI6: 7.863 | HJ6: 10.707 | HK6: 11.646 | HL6: 2 | HM6: Standing still and looking up at me | HN6: Sitting on its back legs and looking up at me. | HO6: Starting at the pinecone. | HP6: That seemed fine. | HQ6: Bending down to stare at the pinecone | HR6: The robot should have starred at the pinecone and shaked its behind, to imitate tail wagging | HS6: Uncontrollable shaking (although I didn't understand this at first) | HT6: Lie down on its side or back | HU6: Head twisting to the side and starting at me | HV6: More prominent head twisting. Perhaps sitting down. | HW6: I think that the behaviours should be more distinct from each other. The differences are too nuanced at the moment. Also, I'm assuming a person interacting with the robot will get a manual telling them about these behaviours - "the robot will wag its tale once it achieves a task". So all you really have to do is make all of the behaviours distinct enough for a human to identify. | HX6: mor.vered@monash.edu | HY6: 2 | HZ6: three_then_five | IA6: 20
A7: 45744.431 | B7: 45744.446 | C7: IP Address | D7: 142.160.47.236 | E7: 100 | F7: 1293 | G7: True | H7: 45744.446 | I7: R_1YBwOSs3BJxnPKF | N7: 49.8221 | O7: -97.0315 | P7: anonymous | Q7: EN | R7: 1 | S7: Yes | T7: Yes | U7: Yes | V7: Yes | W7: Healthcare (e.g. doctor, nurse) | X7: Dog,Cat,Bird,Fish,Other | Y7: Nearly every day or more | Z7: Never | AA7: Never | AB7: Less than once per month | AC7: Waiting for Input | Calcifer is in standby mode, waiting for a command from you. | AD7: Somewhat Confident | AE7: 1.134 | AF7: 15.192 | AG7: 15.469 | AH7: 9 | AI7: Analyzing Pinecone | Calcifer is analyzing a target pinecone to assess its size. | AJ7: Very Confident | AK7: 13.164 | AL7: 16.185 | AM7: 16.7 | AN7: 5 | AO7: Analyzing Pinecone | Calcifer is analyzing a target pinecone to assess its size. | AP7: Very Confident | AQ7: 5.72 | AR7: 16.713 | AS7: 17.092 | AT7: 10 | AU7: Error | Calcifer is signalling to you that it is experiencing a critical error. | AV7: Somewhat Confident | AW7: 18.755 | AX7: 21.338 | AY7: 21.667 | AZ7: 6 | BA7: Found Pinecone | Calcifer is signalling to you that it has found a suitable pinecone. | BB7: Not Very Confident | BC7: 17.878 | BD7: 29.784 | BE7: 32.037 | BF7: 8 | BG7: Waiting for Input | Calcifer is in standby mode, waiting for a command from you. | BH7: Somewhat Confident | BI7: 5.69 | BJ7: 18.13 | BK7: 18.433 | BL7: 12 | BM7: Analyzing Pinecone | Calcifer is analyzing a target pinecone to assess its size. | BN7: Somewhat Confident | BO7: 2.732 | BP7: 14.732 | BQ7: 15.501 | BR7: 12 | BS7: Waiting for Input | Calcifer is in standby mode, waiting for a command from you. | BT7: Somewhat Confident | BU7: 11.42 | BV7: 31.686 | BW7: 32.198 | BX7: 13 | BY7: Found Pinecone | Calcifer is signalling to you that it has found a suitable pinecone. | BZ7: Fully Confident | CA7: 1.536 | CB7: 15.908 | CC7: 16.603 | CD7: 10 | CE7: Confused | Calcifer is signalling to you that it is confused and unsure what to do. | CF7: Somewhat Confident | CG7: 1.244 | CH7: 14.515 | CI7: 15.177 | CJ7: 8 | CK7: Waiting for Input | Calcifer is in standby mode, waiting for a command from you. | CL7: Somewhat Confident | CM7: 1.202 | CN7: 17.273 | CO7: 17.846 | CP7: 11 | CQ7: Analyzing Pinecone | Calcifer is analyzing a target pinecone to assess its size. | CR7: Somewhat Confident | CS7: 0.981 | CT7: 17.175 | CU7: 17.744 | CV7: 7 | CW7: Waiting for Input | Calcifer is in standby mode, waiting for a command from you. | CX7: Somewhat Confident | CY7: 20.708 | CZ7: 31.902 | DA7: 32.604 | DB7: 14 | DC7: Error | Calcifer is signalling to you that it is experiencing a critical error. | DD7: Very Confident | DE7: 2.352 | DF7: 15.088 | DG7: 15.696 | DH7: 8 | DI7: Confused | Calcifer is signalling to you that it is confused and unsure what to do. | DJ7: Somewhat Confident | DK7: 2.5 | DL7: 13.34 | DM7: 13.506 | DN7: 9 | DO7: Waiting for Input | Calcifer is in standby mode, waiting for a command from you. | DP7: Somewhat Confident | DQ7: 5.482 | DR7: 19.232 | DS7: 19.856 | DT7: 8 | DU7: Analyzing Pinecone | Calcifer is analyzing a target pinecone to assess its size. | DV7: Very Confident | DW7: 4.692 | DX7: 38.273 | DY7: 39.381 | DZ7: 11 | EA7: Found Pinecone | Calcifer is signalling to you that it has found a suitable pinecone. | EB7: Somewhat Confident | EC7: 6.251 | ED7: 15.479 | EE7: 15.703 | EF7: 9 | EG7: Error | Calcifer is signalling to you that it is experiencing a critical error. | EH7: Somewhat Confident | EI7: 5.766 | EJ7: 16.577 | EK7: 16.911 | EL7: 10 | EM7: Confused | Calcifer is signalling to you that it is confused and unsure what to do. | EN7: Somewhat Confident | EO7: 1.047 | EP7: 17.628 | EQ7: 18.051 | ER7: 8 | ES7: Waiting for Input | Calcifer is in standby mode, waiting for a command from you. | ET7: Somewhat Confident | EU7: 3.055 | EV7: 15.624 | EW7: 16.1 | EX7: 10 | EY7: Interacting with Pinecone | Calcifer is interacting with a target pinecone. | EZ7: Very Confident | FA7: 13.369 | FB7: 23.177 | FC7: 23.433 | FD7: 9 | FE7: Needs Help | Calcifer is signalling to you that it needs your help. | FF7: Somewhat Confident | FG7: 7.632 | FH7: 18.414 | FI7: 18.703 | FJ7: 8 | FK7: Waiting for Input | Calcifer is in standby mode, waiting for a command from you. | FL7: Very Confident | FM7: 5.256 | FN7: 16.073 | FO7: 16.306 | FP7: 6 | FQ7: Interacting with Pinecone | Calcifer is interacting with a target pinecone. | FR7: Somewhat Confident | FS7: 1.059 | FT7: 21.031 | FU7: 21.202 | FV7: 13 | FW7: Needs Help | Calcifer is signalling to you that it needs your help. | FX7: Somewhat Confident | FY7: 7.035 | FZ7: 19.132 | GA7: 19.3 | GB7: 10 | GC7: Waiting for Input | Calcifer is in standby mode, waiting for a command from you. | GD7: Somewhat Confident | GE7: 5.543 | GF7: 15.485 | GG7: 15.797 | GH7: 8 | GI7: Interacting with Pinecone | Calcifer is interacting with a target pinecone. | GJ7: Very Confident | GK7: 8.08 | GL7: 14.439 | GM7: 14.765 | GN7: 9 | GO7: Needs Help | Calcifer is signalling to you that it needs your help. | GP7: Somewhat Confident | GQ7: 3.889 | GR7: 12.046 | GS7: 12.346 | GT7: 8 | GU7: Waiting for Input | Calcifer is in standby mode, waiting for a command from you. | GV7: Somewhat Confident | GW7: 2.934 | GX7: 19.864 | GY7: 20.179 | GZ7: 10 | HA7: Interacting with Pinecone | Calcifer is interacting with a target pinecone. | HB7: Somewhat Confident | HC7: 4.536 | HD7: 13.383 | HE7: 13.6 | HF7: 8 | HG7: Waiting for Input | Calcifer is in standby mode, waiting for a command from you. | HH7: Somewhat Confident | HI7: 5.088 | HJ7: 26.162 | HK7: 26.457 | HL7: 12 | HM7: Looking up | HN7: Neutral stance, looking up | HO7: Looking down, kneeling down, | HP7: The slight head tilt while looking down was good but i think the front legs down and back legs up while looking down work | HQ7: This was much harder, looking up front legs up back legs down, a slight bum wiggle initially but later on i found that to be more looking like an error | HR7: I dont know if you can make it sit like a dog but that would work | HS7: Any shaky movement, twisting its head while neutral or looking up | HT7: Can it do all 4 legs down and basically make its belly touch the floor? Almost like a shut down state | HU7: All 4 legs up or perhaps just the front ones with its head looking up and rotated slightly is exactly how my dog does it. The little head tilt | HV7: I cant think of a better one than a slight head tilt/rotation | HW7: Several of the videos looked almost exactly the same, i had to check to make sure i was watching the right ones. I'm assuming thats part of the design of your questionnaire but may help to warn about it upfront | HY7: 2 | HZ7: five_then_three | IA7: 12
A8: 45744.433 | B8: 45744.447 | C8: IP Address | D8: 130.194.140.55 | E8: 100 | F8: 1253 | G8: True | H8: 45744.447 | I8: R_4FiDGZYwJzUN2Ux | N8: -37.9108 | O8: 145.1332 | P8: anonymous | Q8: EN | R8: 1 | S8: Yes | T8: Yes | U8: Yes | V8: Yes | W8: Academic (e.g. student, teacher) | X8: No | Y8: Nearly every day or more | Z8: Never | AA8: At least once per week | AB8: A few times per month | AC8: Waiting for Input | Calcifer is in standby mode, waiting for a command from you. | AD8: Not Very Confident | AE8: 9.134 | AF8: 10.669 | AG8: 11.289 | AH8: 2 | AI8: Found Pinecone | Calcifer is signalling to you that it has found a suitable pinecone. | AJ8: Not Very Confident | AK8: 7.828 | AL8: 14.564 | AM8: 14.895 | AN8: 7 | AO8: Found Pinecone | Calcifer is signalling to you that it has found a suitable pinecone. | AP8: Somewhat Confident | AQ8: 9.736 | AR8: 12.384 | AS8: 13.018 | AT8: 2 | AU8: Confused | Calcifer is signalling to you that it is confused and unsure what to do. | AV8: Not Very Confident | AW8: 10.225 | AX8: 12.01 | AY8: 13.211 | AZ8: 2 | BA8: Error | Calcifer is signalling to you that it is experiencing a critical error. | BB8: Not Very Confident | BC8: 12.263 | BD8: 16.856 | BE8: 17.571 | BF8: 3 | BG8: Waiting for Input | Calcifer is in standby mode, waiting for a command from you. | BH8: Not Very Confident | BI8: 9.665 | BJ8: 11.176 | BK8: 11.9 | BL8: 2 | BM8: Found Pinecone | Calcifer is signalling to you that it has found a suitable pinecone. | BN8: Somewhat Confident | BO8: 8.622 | BP8: 10.287 | BQ8: 12.25 | BR8: 2 | BS8: Confused | Calcifer is signalling to you that it is confused and unsure what to do. | BT8: Not Confident at All | BU8: 24.637 | BV8: 27.477 | BW8: 29.118 | BX8: 2 | BY8: Error | Calcifer is signalling to you that it is experiencing a critical error. | BZ8: Not Confident at All | CA8: 8.642 | CB8: 12.106 | CC8: 13.174 | CD8: 2 | CE8: Confused | Calcifer is signalling to you that it is confused and unsure what to do. | CF8: Not Confident at All | CG8: 13.819 | CH8: 15.716 | CI8: 16.543 | CJ8: 2 | CK8: Waiting for Input | Calcifer is in standby mode, waiting for a command from you. | CL8: Somewhat Confident | CM8: 5.904 | CN8: 10.321 | CO8: 10.925 | CP8: 4 | CQ8: Found Pinecone | Calcifer is signalling to you that it has found a suitable pinecone. | CR8: Somewhat Confident | CS8: 11.231 | CT8: 13.76 | CU8: 14.505 | CV8: 2 | CW8: Waiting for Input | Calcifer is in standby mode, waiting for a command from you. | CX8: Not Very Confident | CY8: 11.046 | CZ8: 12.478 | DA8: 13.177 | DB8: 2 | DC8: Waiting for Input | Calcifer is in standby mode, waiting for a command from you. | DD8: Not Very Confident | DE8: 6.619 | DF8: 10.524 | DG8: 11.286 | DH8: 3 | DI8: Confused | Calcifer is signalling to you that it is confused and unsure what to do. | DJ8: Somewhat Confident | DK8: 7.727 | DL8: 9.47 | DM8: 10.17 | DN8: 2 | DO8: Waiting for Input | Calcifer is in standby mode, waiting for a command from you. | DP8: Somewhat Confident | DQ8: 11.305 | DR8: 15.617 | DS8: 16.26 | DT8: 3 | DU8: Analyzing Pinecone | Calcifer is analyzing a target pinecone to assess its size. | DV8: Not Very Confident | DW8: 9.854 | DX8: 16.191 | DY8: 17.907 | DZ8: 4 | EA8: Waiting for Input | Calcifer is in standby mode, waiting for a command from you. | EB8: Not Very Confident | EC8: 14.872 | ED8: 16.831 | EE8: 17.698 | EF8: 2 | EG8: Waiting for Input | Calcifer is in standby mode, waiting for a command from you. | EH8: Not Very Confident | EI8: 9.244 | EJ8: 13.451 | EK8: 16.416 | EL8: 2 | EM8: Confused | Calcifer is signalling to you that it is confused and unsure what to do. | EN8: Somewhat Confident | EO8: 8.54 | EP8: 11.979 | EQ8: 12.982 | ER8: 3 | ES8: Waiting for Input | Calcifer is in standby mode, waiting for a command from you. | ET8: Very Confident | EU8: 9.284 | EV8: 10.483 | EW8: 11.126 | EX8: 2 | EY8: Interacting with Pinecone | Calcifer is interacting with a target pinecone. | EZ8: Fully Confident | FA8: 15.841 | FB8: 19.234 | FC8: 20.055 | FD8: 2 | FE8: Needs Help | Calcifer is signalling to you that it needs your help. | FF8: Not Very Confident | FG8: 11.962 | FH8: 13.978 | FI8: 16.589 | FJ8: 2 | FK8: Waiting for Input | Calcifer is in standby mode, waiting for a command from you. | FL8: Somewhat Confident | FM8: 8.415 | FN8: 11.113 | FO8: 11.835 | FP8: 2 | FQ8: Interacting with Pinecone | Calcifer is interacting with a target pinecone. | FR8: Fully Confident | FS8: 12.328 | FT8: 15.71 | FU8: 16.691 | FV8: 2 | FW8: Waiting for Input | Calcifer is in standby mode, waiting for a command from you. | FX8: Not Very Confident | FY8: 19.49 | FZ8: 27.777 | GA8: 30.036 | GB8: 4 | GC8: Waiting for Input | Calcifer is in standby mode, waiting for a command from you. | GD8: Very Confident | GE8: 9.435 | GF8: 11.172 | GG8: 11.719 | GH8: 2 | GI8: Interacting with Pinecone | Calcifer is interacting with a target pinecone. | GJ8: Very Confident | GK8: 11.315 | GL8: 13.06 | GM8: 15.957 | GN8: 2 | GO8: Waiting for Input | Calcifer is in standby mode, waiting for a command from you. | GP8: Somewhat Confident | GQ8: 12.071 | GR8: 14.975 | GS8: 16.259 | GT8: 2 | GU8: Waiting for Input | Calcifer is in standby mode, waiting for a command from you. | GV8: Somewhat Confident | GW8: 10.43 | GX8: 12.82 | GY8: 13.43 | GZ8: 2 | HA8: Interacting with Pinecone | Calcifer is interacting with a target pinecone. | HB8: Very Confident | HC8: 8.347 | HD8: 9.523 | HE8: 10.318 | HF8: 2 | HG8: Waiting for Input | Calcifer is in standby mode, waiting for a command from you. | HH8: Somewhat Confident | HI8: 9.319 | HJ8: 11.528 | HK8: 12.179 | HL8: 3 | HM8: The robot is facing towards me and staring at me, sometimes with a tilted head(or body). | HN8: Facing towards me and staring at me, like what a dog would do. | HO8: Staring at the pinecone. | HP8: Staring at the pinecone and also moving its head around to scan the pinecone. | HQ8: Staring at the pinecone. | HR8: Staring at the pinecone, then stare at me, repeat for a few time to get my attention. | HS8: Shaking? I'm not sure. | HT8: I'm not sure, maybe lay on the ground, pretending it's sick. | HU8: Tilted head/body. | HV8: Tilted head/body. | HX8: Haoyang.Jiang@monash.edu | HY8: 2 | HZ8: three_then_five | IA8: 20
